Workbook

Sheet NOMINA TEJIDO 
A1: 1 | AA1: MARTES 06/03 | AF1: MIERCOLES 07/03 | AK1: JUEVES 08/03 | AP1: VIERNES 09/03 | AU1: SABADO 10/03 | BU1: 1
A2: 2 | B2: TEJIDO | T2: SUELDO ESTIMADO FALTA SOLO RELOJ | U2: BONO | V2: DEL 08 AL 14 ENERO 24 | X2: 7.18 | Y2: 7.18 | BA2: 0 | BU2: 2
A3: 3 | E3: L | G3: M | I3: M | K3: J | M3: V | O3: S | R3: COSTOS | V3: 0 | W3: NOMINA | X3: PXP | Y3: PXA | Z3: TOTAL | AA3: INC | AB3: NOMINA | AC3: PXP | AD3: PXA | AE3: TOTAL | AF3: INC | AG3: NOMINA | AH3: PXP | AI3: PXA | AJ3: TOTAL | AK3: INC | AL3: NOMINA | AM3: PXP | AN3: PXA | AO3: TOTAL | AP3: INC | AQ3: NOMINA | AR3: PXP | AS3: PXA | AT3: TOTAL | AU3: INC | AV3: NOMINA | AW3: PXP | AX3: PXA | AY3: TOTAL | BB3: CB | BC3: FP | BD3: L | BE3: R | BI3: INC | BJ3: B ASISTENCIA | BK3: T EXT | BM3: PRIMAS | BN3: PAGO EXTRA | BQ3: 3 | BR3: =0.167*4+4 -> 4.668 | BU3: 3
B4: 164 | C4: =+C3+1 -> 1 | E4: 1 | G4: 1 | I4: 1 | K4: 1 | M4: 1 | O4: 1 | Q4: =IF((E4+G4+I4+K4+M4+O4)=6,1,0) -> 1 | R4: =IF(Q4=1,1550,850) -> 1550 | S4: =+BH4 -> 0 | T4: =+BA4 -> 929 | U4: =+BP4 -> 0 | V4: =+BG4 -> BONO+ B ASIS | W4: =(R4-86.16)/6*E4 -> 243.97333 | X4: =$Y$2*E4*Q4 -> 7.18 | Y4: =$Y$2*E4*Q4 -> 7.18 | Z4: =Y4+X4+W4 -> 258.33333 | AB4: =(R4-86.16)/6*G4 -> 243.97333 | AC4: =$Y$2*G4*Q4 -> 7.18 | AD4: =$Y$2*G4*Q4 -> 7.18 | AE4: =AD4+AC4+AB4 -> 258.33333 | AG4: =(R4-86.16)/6*I4 -> 243.97333 | AH4: =$Y$2*I4*Q4 -> 7.18 | AI4: =$Y$2*I4*Q4 -> 7.18 | AJ4: =AI4+AH4+AG4 -> 258.33333 | AL4: =(R4-86.16)/6*K4 -> 243.97333 | AM4: =$Y$2*K4*Q4 -> 7.18 | AN4: =$Y$2*K4*Q4 -> 7.18 | AO4: =AN4+AM4+AL4 -> 258.33333 | AQ4: =(R4-86.16)/6*M4 -> 243.97333 | AR4: =$Y$2*M4*Q4 -> 7.18 | AS4: =$Y$2*M4*Q4 -> 7.18 | AT4: =AS4+AR4+AQ4 -> 258.33333 | AV4: =(R4-86.16)/6*O4 -> 243.97333 | AW4: =$Y$2*O4*Q4 -> 7.18 | AX4: =$Y$2*O4*Q4 -> 7.18 | AY4: =AX4+AW4+AV4 -> 258.33333 | AZ4: =+AY4+AT4+AO4++AJ4+AE4+Z4 -> 1550 | BA4: 929 | BG4: BONO+ B ASIS
A5: 420 | B5: 2 | C5: =+C4+1 -> 2 | D5: Antunez Requejo Gabriela | E5: 1 | G5: 1 | I5: 1 | K5: 1 | M5: 1 | O5: 1 | Q5: =IF((E5+G5+I5+K5+M5+O5)=6,1,0) -> 1 | R5: =IF(Q5=1,1550,850) -> 1550 | S5: =+BH5 -> 0 | T5: =+BA5 -> 2100 | U5: =+BP5 -> 0 | V5: =+BG5 -> BONO+ B ASIS | W5: =(R5-86.16)/6*E5 -> 243.97333 | X5: =$Y$2*E5*Q5 -> 7.18 | Y5: =$Y$2*E5*Q5 -> 7.18 | Z5: =Y5+X5+W5 -> 258.33333 | AB5: =(R5-86.16)/6*G5 -> 243.97333 | AC5: =$Y$2*G5*Q5 -> 7.18 | AD5: =$Y$2*G5*Q5 -> 7.18 | AE5: =AD5+AC5+AB5 -> 258.33333 | AG5: =(R5-86.16)/6*I5 -> 243.97333 | AH5: =$Y$2*I5*Q5 -> 7.18 | AI5: =$Y$2*I5*Q5 -> 7.18 | AJ5: =AI5+AH5+AG5 -> 258.33333 | AL5: =(R5-86.16)/6*K5 -> 243.97333 | AM5: =$Y$2*K5*Q5 -> 7.18 | AN5: =$Y$2*K5*Q5 -> 7.18 | AO5: =AN5+AM5+AL5 -> 258.33333 | AQ5: =(R5-86.16)/6*M5 -> 243.97333 | AR5: =$Y$2*M5*Q5 -> 7.18 | AS5: =$Y$2*M5*Q5 -> 7.18 | AT5: =AS5+AR5+AQ5 -> 258.33333 | AV5: =(R5-86.16)/6*O5 -> 243.97333 | AW5: =$Y$2*O5*Q5 -> 7.18 | AX5: =$Y$2*O5*Q5 -> 7.18 | AY5: =AX5+AW5+AV5 -> 258.33333 | AZ5: =+AY5+AT5+AO5++AJ5+AE5+Z5 -> 1550 | BA5: =((AZ5-BB5-BC5-BD5-BE5-BF5)+BI5+BJ5+BK5+BL5+BM5+BN5+BO5) -> 2100 | BG5: BONO+ B ASIS | BI5: 300 | BJ5: 250 | BU5: 420
A6: 424 | B6: 6 | C6: =+C5+1 -> 3 | D6: Balderas Balderas Myriam Ivet | E6: 1 | G6: 1 | I6: 1 | K6: 1 | M6: 1 | O6: 1 | Q6: =IF((E6+G6+I6+K6+M6+O6)=6,1,0) -> 1 | R6: 3000 | S6: =+BH6 -> 0 | T6: =+BA6 -> 3000 | U6: =+BP6 -> 0 | V6: =+BG6 -> 0 | W6: =(R6-86.16)/6*E6 -> 485.64 | X6: =$Y$2*E6*Q6 -> 7.18 | Y6: =$Y$2*E6*Q6 -> 7.18 | Z6: =Y6+X6+W6 -> 500 | AB6: =(R6-86.16)/6*G6 -> 485.64 | AC6: =$Y$2*G6*Q6 -> 7.18 | AD6: =$Y$2*G6*Q6 -> 7.18 | AE6: =AD6+AC6+AB6 -> 500 | AG6: =(R6-86.16)/6*I6 -> 485.64 | AH6: =$Y$2*I6*Q6 -> 7.18 | AI6: =$Y$2*I6*Q6 -> 7.18 | AJ6: =AI6+AH6+AG6 -> 500 | AL6: =(R6-86.16)/6*K6 -> 485.64 | AM6: =$Y$2*K6*Q6 -> 7.18 | AN6: =$Y$2*K6*Q6 -> 7.18 | AO6: =AN6+AM6+AL6 -> 500 | AQ6: =(R6-86.16)/6*M6 -> 485.64 | AR6: =$Y$2*M6*Q6 -> 7.18 | AS6: =$Y$2*M6*Q6 -> 7.18 | AT6: =AS6+AR6+AQ6 -> 500 | AV6: =(R6-86.16)/6*O6 -> 485.64 | AW6: =$Y$2*O6*Q6 -> 7.18 | AX6: =$Y$2*O6*Q6 -> 7.18 | AY6: =AX6+AW6+AV6 -> 500 | AZ6: =+AY6+AT6+AO6++AJ6+AE6+Z6 -> 3000 | BA6: =((AZ6-BB6-BC6-BD6-BE6-BF6)+BI6+BJ6+BK6+BL6+BM6+BN6+BO6) -> 3000 | BU6: 424
B7: 149 | C7: =+C6+1 -> 4 | D7: Carrillo Alvarado Erika Miranda | E7: 1 | G7: 1 | I7: 1 | K7: 1 | M7: 1 | O7: 1 | Q7: =IF((E7+G7+I7+K7+M7+O7)=6,1,0) -> 1 | R7: =IF(Q7=1,1550,850) -> 1550 | S7: =+BH7 -> 0 | T7: =+BA7 -> 1800 | U7: =+BP7 -> 0 | V7: =+BG7 -> BONO+ B ASIS | W7: =(R7-86.16)/6*E7 -> 243.97333 | X7: =$Y$2*E7*Q7 -> 7.18 | Y7: =$Y$2*E7*Q7 -> 7.18 | Z7: =Y7+X7+W7 -> 258.33333 | AB7: =(R7-86.16)/6*G7 -> 243.97333 | AC7: =$Y$2*G7*Q7 -> 7.18 | AD7: =$Y$2*G7*Q7 -> 7.18 | AE7: =AD7+AC7+AB7 -> 258.33333 | AG7: =(R7-86.16)/6*I7 -> 243.97333 | AH7: =$Y$2*I7*Q7 -> 7.18 | AI7: =$Y$2*I7*Q7 -> 7.18 | AJ7: =AI7+AH7+AG7 -> 258.33333 | AL7: =(R7-86.16)/6*K7 -> 243.97333 | AM7: =$Y$2*K7*Q7 -> 7.18 | AN7: =$Y$2*K7*Q7 -> 7.18 | AO7: =AN7+AM7+AL7 -> 258.33333 | AQ7: =(R7-86.16)/6*M7 -> 243.97333 | AR7: =$Y$2*M7*Q7 -> 7.18 | AS7: =$Y$2*M7*Q7 -> 7.18 | AT7: =AS7+AR7+AQ7 -> 258.33333 | AV7: =(R7-86.16)/6*O7 -> 243.97333 | AW7: =$Y$2*O7*Q7 -> 7.18 | AX7: =$Y$2*O7*Q7 -> 7.18 | AY7: =AX7+AW7+AV7 -> 258.33333 | AZ7: =+AY7+AT7+AO7++AJ7+AE7+Z7 -> 1550 | BA7: =((AZ7-BB7-BC7-BD7-BE7-BF7)+BI7+BJ7+BK7+BL7+BM7+BN7+BO7) -> 1800 | BG7: BONO+ B ASIS | BI7: 100 | BJ7: 150
B8: 95 | C8: =+C7+1 -> 5 | D8: Carrillo Delgado Judith | E8: 1 | G8: 1 | I8: 1 | K8: 1 | M8: 1 | O8: 1 | Q8: =IF((E8+G8+I8+K8+M8+O8)=6,1,0) -> 1 | R8: =IF(Q8=1,1550,850) -> 1550 | S8: =+BH8 -> 0 | T8: =+BA8 -> 1950 | U8: =+BP8 -> 0 | V8: =+BG8 -> BONO+ B ASIS | W8: =(R8-86.16)/6*E8 -> 243.97333 | X8: =$Y$2*E8*Q8 -> 7.18 | Y8: =$Y$2*E8*Q8 -> 7.18 | Z8: =Y8+X8+W8 -> 258.33333 | AB8: =(R8-86.16)/6*G8 -> 243.97333 | AC8: =$Y$2*G8*Q8 -> 7.18 | AD8: =$Y$2*G8*Q8 -> 7.18 | AE8: =AD8+AC8+AB8 -> 258.33333 | AG8: =(R8-86.16)/6*I8 -> 243.97333 | AH8: =$Y$2*I8*Q8 -> 7.18 | AI8: =$Y$2*I8*Q8 -> 7.18 | AJ8: =AI8+AH8+AG8 -> 258.33333 | AL8: =(R8-86.16)/6*K8 -> 243.97333 | AM8: =$Y$2*K8*Q8 -> 7.18 | AN8: =$Y$2*K8*Q8 -> 7.18 | AO8: =AN8+AM8+AL8 -> 258.33333 | AQ8: =(R8-86.16)/6*M8 -> 243.97333 | AR8: =$Y$2*M8*Q8 -> 7.18 | AS8: =$Y$2*M8*Q8 -> 7.18 | AT8: =AS8+AR8+AQ8 -> 258.33333 | AV8: =(R8-86.16)/6*O8 -> 243.97333 | AW8: =$Y$2*O8*Q8 -> 7.18 | AX8: =$Y$2*O8*Q8 -> 7.18 | AY8: =AX8+AW8+AV8 -> 258.33333 | AZ8: =+AY8+AT8+AO8++AJ8+AE8+Z8 -> 1550 | BA8: =((AZ8-BB8-BC8-BD8-BE8-BF8)+BI8+BJ8+BK8+BL8+BM8+BN8+BO8) -> 1950 | BG8: BONO+ B ASIS | BI8: 250 | BJ8: 150
B9: 59 | C9: =+C8+1 -> 6 | D9: Castro Viaña Mario Ivan | E9: 1 | G9: 1 | I9: 1 | K9: 1 | M9: 1 | O9: 1 | Q9: =IF((E9+G9+I9+K9+M9+O9)=6,1,0) -> 1 | R9: =IF(Q9=1,1550,850) -> 1550 | S9: =+BH9 -> 0 | T9: =+BA9 -> 1950 | U9: =+BP9 -> 0 | V9: =+BG9 -> BONO+ B ASIS | W9: =(R9-86.16)/6*E9 -> 243.97333 | X9: =$Y$2*E9*Q9 -> 7.18 | Y9: =$Y$2*E9*Q9 -> 7.18 | Z9: =Y9+X9+W9 -> 258.33333 | AB9: =(R9-86.16)/6*G9 -> 243.97333 | AC9: =$Y$2*G9*Q9 -> 7.18 | AD9: =$Y$2*G9*Q9 -> 7.18 | AE9: =AD9+AC9+AB9 -> 258.33333 | AG9: =(R9-86.16)/6*I9 -> 243.97333 | AH9: =$Y$2*I9*Q9 -> 7.18 | AI9: =$Y$2*I9*Q9 -> 7.18 | AJ9: =AI9+AH9+AG9 -> 258.33333 | AL9: =(R9-86.16)/6*K9 -> 243.97333 | AM9: =$Y$2*K9*Q9 -> 7.18 | AN9: =$Y$2*K9*Q9 -> 7.18 | AO9: =AN9+AM9+AL9 -> 258.33333 | AQ9: =(R9-86.16)/6*M9 -> 243.97333 | AR9: =$Y$2*M9*Q9 -> 7.18 | AS9: =$Y$2*M9*Q9 -> 7.18 | AT9: =AS9+AR9+AQ9 -> 258.33333 | AV9: =(R9-86.16)/6*O9 -> 243.97333 | AW9: =$Y$2*O9*Q9 -> 7.18 | AX9: =$Y$2*O9*Q9 -> 7.18 | AY9: =AX9+AW9+AV9 -> 258.33333 | AZ9: =+AY9+AT9+AO9++AJ9+AE9+Z9 -> 1550 | BA9: =((AZ9-BB9-BC9-BD9-BE9-BF9)+BI9+BJ9+BK9+BL9+BM9+BN9+BO9) -> 1950 | BG9: BONO+ B ASIS | BI9: 250 | BJ9: 150
B10: 73 | C10: =+C9+1 -> 7 | D10: Garcia Ortega Leslie Coraima | E10: 1 | G10: 1 | I10: 1 | K10: 1 | M10: 1 | O10: 1 | Q10: =IF((E10+G10+I10+K10+M10+O10)=6,1,0) -> 1 | R10: =IF(Q10=1,1550,850) -> 1550 | S10: =+BH10 -> 0 | T10: =+BA10 -> 1950 | U10: =+BP10 -> 0 | V10: =+BG10 -> BONO+ B ASIS | W10: =(R10-86.16)/6*E10 -> 243.97333 | X10: =$Y$2*E10*Q10 -> 7.18 | Y10: =$Y$2*E10*Q10 -> 7.18 | Z10: =Y10+X10+W10 -> 258.33333 | AB10: =(R10-86.16)/6*G10 -> 243.97333 | AC10: =$Y$2*G10*Q10 -> 7.18 | AD10: =$Y$2*G10*Q10 -> 7.18 | AE10: =AD10+AC10+AB10 -> 258.33333 | AG10: =(R10-86.16)/6*I10 -> 243.97333 | AH10: =$Y$2*I10*Q10 -> 7.18 | AI10: =$Y$2*I10*Q10 -> 7.18 | AJ10: =AI10+AH10+AG10 -> 258.33333 | AL10: =(R10-86.16)/6*K10 -> 243.97333 | AM10: =$Y$2*K10*Q10 -> 7.18 | AN10: =$Y$2*K10*Q10 -> 7.18 | AO10: =AN10+AM10+AL10 -> 258.33333 | AQ10: =(R10-86.16)/6*M10 -> 243.97333 | AR10: =$Y$2*M10*Q10 -> 7.18 | AS10: =$Y$2*M10*Q10 -> 7.18 | AT10: =AS10+AR10+AQ10 -> 258.33333 | AV10: =(R10-86.16)/6*O10 -> 243.97333 | AW10: =$Y$2*O10*Q10 -> 7.18 | AX10: =$Y$2*O10*Q10 -> 7.18 | AY10: =AX10+AW10+AV10 -> 258.33333 | AZ10: =+AY10+AT10+AO10++AJ10+AE10+Z10 -> 1550 | BA10: =((AZ10-BB10-BC10-BD10-BE10-BF10)+BI10+BJ10+BK10+BL10+BM10+BN10+BO10) -> 1950 | BG10: BONO+ B ASIS | BI10: 250 | BJ10: 150
A11: 424 | B11: 26 | C11: =+C10+1 -> 8 | D11: Medrano Suarez Jose Adolfo | E11: 1 | G11: 1 | I11: 1 | K11: 1 | M11: 1 | O11: 1 | Q11: =IF((E11+G11+I11+K11+M11+O11)=6,1,0) -> 1 | R11: 2500 | S11: =+BH11 -> 0 | T11: =+BA11 -> 2500 | U11: =+BP11 -> 0 | V11: =+BG11 -> 0 | W11: =(R11-86.16)/6*E11 -> 402.30667 | X11: =$Y$2*E11*Q11 -> 7.18 | Y11: =$Y$2*E11*Q11 -> 7.18 | Z11: =Y11+X11+W11 -> 416.66667 | AB11: =(R11-86.16)/6*G11 -> 402.30667 | AC11: =$Y$2*G11*Q11 -> 7.18 | AD11: =$Y$2*G11*Q11 -> 7.18 | AE11: =AD11+AC11+AB11 -> 416.66667 | AG11: =(R11-86.16)/6*I11 -> 402.30667 | AH11: =$Y$2*I11*Q11 -> 7.18 | AI11: =$Y$2*I11*Q11 -> 7.18 | AJ11: =AI11+AH11+AG11 -> 416.66667 | AL11: =(R11-86.16)/6*K11 -> 402.30667 | AM11: =$Y$2*K11*Q11 -> 7.18 | AN11: =$Y$2*K11*Q11 -> 7.18 | AO11: =AN11+AM11+AL11 -> 416.66667 | AQ11: =(R11-86.16)/6*M11 -> 402.30667 | AR11: =$Y$2*M11*Q11 -> 7.18 | AS11: =$Y$2*M11*Q11 -> 7.18 | AT11: =AS11+AR11+AQ11 -> 416.66667 | AV11: =(R11-86.16)/6*O11 -> 402.30667 | AW11: =$Y$2*O11*Q11 -> 7.18 | AX11: =$Y$2*O11*Q11 -> 7.18 | AY11: =AX11+AW11+AV11 -> 416.66667 | AZ11: =+AY11+AT11+AO11++AJ11+AE11+Z11 -> 2500 | BA11: =((AZ11-BB11-BC11-BD11-BE11-BF11)+BI11+BJ11+BK11+BL11+BM11+BN11+BO11) -> 2500 | BU11: 424
B12: 169 | C12: =+C11+1 -> 9 | D12: Ramirez Requejo Maria Guadalupe | E12: 1 | G12: 1 | I12: 1 | K12: 1 | M12: 1 | O12: 1 | Q12: =IF((E12+G12+I12+K12+M12+O12)=6,1,0) -> 1 | R12: =IF(Q12=1,1550,850) -> 1550 | S12: =+BH12 -> 0 | T12: =+BA12 -> 1700 | U12: =+BP12 -> 0 | V12: =+BG12 -> BONO | W12: =(R12-86.16)/6*E12 -> 243.97333 | X12: =$Y$2*E12*Q12 -> 7.18 | Y12: =$Y$2*E12*Q12 -> 7.18 | Z12: =Y12+X12+W12 -> 258.33333 | AB12: =(R12-86.16)/6*G12 -> 243.97333 | AC12: =$Y$2*G12*Q12 -> 7.18 | AD12: =$Y$2*G12*Q12 -> 7.18 | AE12: =AD12+AC12+AB12 -> 258.33333 | AG12: =(R12-86.16)/6*I12 -> 243.97333 | AH12: =$Y$2*I12*Q12 -> 7.18 | AI12: =$Y$2*I12*Q12 -> 7.18 | AJ12: =AI12+AH12+AG12 -> 258.33333 | AL12: =(R12-86.16)/6*K12 -> 243.97333 | AM12: =$Y$2*K12*Q12 -> 7.18 | AN12: =$Y$2*K12*Q12 -> 7.18 | AO12: =AN12+AM12+AL12 -> 258.33333 | AQ12: =(R12-86.16)/6*M12 -> 243.97333 | AR12: =$Y$2*M12*Q12 -> 7.18 | AS12: =$Y$2*M12*Q12 -> 7.18 | AT12: =AS12+AR12+AQ12 -> 258.33333 | AV12: =(R12-86.16)/6*O12 -> 243.97333 | AW12: =$Y$2*O12*Q12 -> 7.18 | AX12: =$Y$2*O12*Q12 -> 7.18 | AY12: =AX12+AW12+AV12 -> 258.33333 | AZ12: =+AY12+AT12+AO12++AJ12+AE12+Z12 -> 1550 | BA12: =((AZ12-BB12-BC12-BD12-BE12-BF12)+BI12+BJ12+BK12+BL12+BM12+BN12+BO12) -> 1700 | BG12: BONO | BJ12: 150
B13: 152 | C13: =+C12+1 -> 10 | D13: Ruiz Valenzuela Cynthia Marissa | E13: 1 | G13: 1 | I13: 1 | K13: 1 | M13: 1 | O13: 1 | Q13: =IF((E13+G13+I13+K13+M13+O13)=6,1,0) -> 1 | R13: =IF(Q13=1,1550,850) -> 1550 | S13: =+BH13 -> 0 | T13: =+BA13 -> 2000 | U13: =+BP13 -> 0 | V13: =+BG13 -> BONO+B ASIS | W13: =(R13-86.16)/6*E13 -> 243.97333 | X13: =$Y$2*E13*Q13 -> 7.18 | Y13: =$Y$2*E13*Q13 -> 7.18 | Z13: =Y13+X13+W13 -> 258.33333 | AB13: =(R13-86.16)/6*G13 -> 243.97333 | AC13: =$Y$2*G13*Q13 -> 7.18 | AD13: =$Y$2*G13*Q13 -> 7.18 | AE13: =AD13+AC13+AB13 -> 258.33333 | AG13: =(R13-86.16)/6*I13 -> 243.97333 | AH13: =$Y$2*I13*Q13 -> 7.18 | AI13: =$Y$2*I13*Q13 -> 7.18 | AJ13: =AI13+AH13+AG13 -> 258.33333 | AL13: =(R13-86.16)/6*K13 -> 243.97333 | AM13: =$Y$2*K13*Q13 -> 7.18 | AN13: =$Y$2*K13*Q13 -> 7.18 | AO13: =AN13+AM13+AL13 -> 258.33333 | AQ13: =(R13-86.16)/6*M13 -> 243.97333 | AR13: =$Y$2*M13*Q13 -> 7.18 | AS13: =$Y$2*M13*Q13 -> 7.18 | AT13: =AS13+AR13+AQ13 -> 258.33333 | AV13: =(R13-86.16)/6*O13 -> 243.97333 | AW13: =$Y$2*O13*Q13 -> 7.18 | AX13: =$Y$2*O13*Q13 -> 7.18 | AY13: =AX13+AW13+AV13 -> 258.33333 | AZ13: =+AY13+AT13+AO13++AJ13+AE13+Z13 -> 1550 | BA13: =((AZ13-BB13-BC13-BD13-BE13-BF13)+BI13+BJ13+BK13+BL13+BM13+BN13+BO13) -> 2000 | BG13: BONO+B ASIS | BI13: 300 | BJ13: 150
B14: 146 | C14: =+C13+1 -> 11 | D14: Salazar Martinez Yohana Cecilia | E14: 1 | G14: 1 | I14: 1 | K14: 1 | M14: 1 | O14: 1 | Q14: =IF((E14+G14+I14+K14+M14+O14)=6,1,0) -> 1 | R14: =IF(Q14=1,1550,850) -> 1550 | S14: =+BH14 -> 0 | T14: =+BA14 -> 1950 | U14: =+BP14 -> 0 | V14: =+BG14 -> BONO+B ASIS | W14: =(R14-86.16)/6*E14 -> 243.97333 | X14: =$Y$2*E14*Q14 -> 7.18 | Y14: =$Y$2*E14*Q14 -> 7.18 | Z14: =Y14+X14+W14 -> 258.33333 | AB14: =(R14-86.16)/6*G14 -> 243.97333 | AC14: =$Y$2*G14*Q14 -> 7.18 | AD14: =$Y$2*G14*Q14 -> 7.18 | AE14: =AD14+AC14+AB14 -> 258.33333 | AG14: =(R14-86.16)/6*I14 -> 243.97333 | AH14: =$Y$2*I14*Q14 -> 7.18 | AI14: =$Y$2*I14*Q14 -> 7.18 | AJ14: =AI14+AH14+AG14 -> 258.33333 | AL14: =(R14-86.16)/6*K14 -> 243.97333 | AM14: =$Y$2*K14*Q14 -> 7.18 | AN14: =$Y$2*K14*Q14 -> 7.18 | AO14: =AN14+AM14+AL14 -> 258.33333 | AQ14: =(R14-86.16)/6*M14 -> 243.97333 | AR14: =$Y$2*M14*Q14 -> 7.18 | AS14: =$Y$2*M14*Q14 -> 7.18 | AT14: =AS14+AR14+AQ14 -> 258.33333 | AV14: =(R14-86.16)/6*O14 -> 243.97333 | AW14: =$Y$2*O14*Q14 -> 7.18 | AX14: =$Y$2*O14*Q14 -> 7.18 | AY14: =AX14+AW14+AV14 -> 258.33333 | AZ14: =+AY14+AT14+AO14++AJ14+AE14+Z14 -> 1550 | BA14: =((AZ14-BB14-BC14-BD14-BE14-BF14)+BI14+BJ14+BK14+BL14+BM14+BN14+BO14) -> 1950 | BG14: BONO+B ASIS | BI14: 250 | BJ14: 150
A15: 470 | B15: 51 | C15: =+C14+1 -> 12 | D15: Valenzuela Rosales Jose Miguel | E15: 1 | G15: 1 | I15: 1 | K15: 1 | M15: 1 | O15: 1 | Q15: =IF((E15+G15+I15+K15+M15+O15)=6,1,0) -> 1 | R15: 3000 | S15: =+BH15 -> 0 | T15: =+BA15 -> 5585.71 | U15: =+BP15 -> 0 | V15: =+BG15 -> BONO+FINIQUITO | W15: =(R15-86.16)/6*E15 -> 485.64 | X15: =$Y$2*E15*Q15 -> 7.18 | Y15: =$Y$2*E15*Q15 -> 7.18 | Z15: =Y15+X15+W15 -> 500 | AB15: =(R15-86.16)/6*G15 -> 485.64 | AC15: =$Y$2*G15*Q15 -> 7.18 | AD15: =$Y$2*G15*Q15 -> 7.18 | AE15: =AD15+AC15+AB15 -> 500 | AG15: =(R15-86.16)/6*I15 -> 485.64 | AH15: =$Y$2*I15*Q15 -> 7.18 | AI15: =$Y$2*I15*Q15 -> 7.18 | AJ15: =AI15+AH15+AG15 -> 500 | AL15: =(R15-86.16)/6*K15 -> 485.64 | AM15: =$Y$2*K15*Q15 -> 7.18 | AN15: =$Y$2*K15*Q15 -> 7.18 | AO15: =AN15+AM15+AL15 -> 500 | AQ15: =(R15-86.16)/6*M15 -> 485.64 | AR15: =$Y$2*M15*Q15 -> 7.18 | AS15: =$Y$2*M15*Q15 -> 7.18 | AT15: =AS15+AR15+AQ15 -> 500 | AV15: =(R15-86.16)/6*O15 -> 485.64 | AW15: =$Y$2*O15*Q15 -> 7.18 | AX15: =$Y$2*O15*Q15 -> 7.18 | AY15: =AX15+AW15+AV15 -> 500 | AZ15: =+AY15+AT15+AO15++AJ15+AE15+Z15 -> 3000 | BA15: =((AZ15-BB15-BC15-BD15-BE15-BF15)+BI15+BJ15+BK15+BL15+BM15+BN15+BO15) -> 5585.71 | BG15: BONO+FINIQUITO | BI15: 1000 | BL15: 1585.71 | BU15: 470
A16: 429 | E16: =SUM(E4:E15) -> 12 | G16: =SUM(G4:G15) -> 12 | I16: =SUM(I4:I15) -> 12 | K16: =SUM(K4:K15) -> 12 | M16: =SUM(M4:M15) -> 12 | O16: =SUM(O4:O15) -> 12 | BU16: 429
A17: 430 | BU17: 430
A18: 431 | B18: REAL | C18: PR | G18: L | I18: M | K18: M | M18: J | O18: V | Q18: S | BU18: 431
A19: 432 | B19: =E16 -> 12 | C19: =G25 -> 12 | D19: =+B19-C19 -> 0 | R19: PROM | BU19: 432
A20: 433 | B20: =G16 -> 12 | C20: =I25 -> 12 | D20: =+B20-C20 -> 0 | E20: LIDER | G20: 1 | I20: 1 | K20: 1 | M20: 1 | O20: 1 | Q20: 1 | R20: =AVERAGE(G20,I20,K20,M20,O20,Q20) -> 1 | BU20: 433
A21: 434 | B21: =I16 -> 12 | C21: =K25 -> 12 | D21: =+B21-C21 -> 0 | E21: CALIDAD | G21: 1 | I21: 1 | K21: 1 | M21: 1 | O21: 1 | Q21: 1 | R21: =AVERAGE(G21,I21,K21,M21,O21,Q21) -> 1 | BU21: 434
A22: 435 | B22: =K16 -> 12 | C22: =M25 -> 12 | D22: =+B22-C22 -> 0 | E22: MECANICO | G22: 2 | I22: 2 | K22: 2 | M22: 2 | O22: 2 | Q22: 2 | R22: =AVERAGE(G22,I22,K22,M22,O22,Q22) -> 2 | BU22: 435
A23: 436 | B23: =M16 -> 12 | C23: =O25 -> 12 | D23: =+B23-C23 -> 0 | E23: MANUAL | G23: 8 | I23: 8 | K23: 8 | M23: 8 | O23: 8 | Q23: 8 | R23: =AVERAGE(G23,I23,K23,M23,O23,Q23) -> 8 | BU23: 436
A24: 437 | B24: =O16 -> 12 | C24: =Q25 -> 12 | D24: =+B24-C24 -> 0 | E24: MTTO | G24: 0 | I24: 0 | K24: 0 | M24: 0 | O24: 0 | Q24: 0 | R24: =AVERAGE(G24,I24,K24,M24,O24,Q24) -> 0 | BU24: 437
A25: 438 | G25: =SUM(G20:G24) -> 12 | I25: =SUM(I20:I24) -> 12 | K25: =SUM(K20:K24) -> 12 | M25: =SUM(M20:M24) -> 12 | O25: =SUM(O20:O24) -> 12 | Q25: =SUM(Q20:Q24) -> 12 | R25: =AVERAGE(G25,I25,K25,M25,O25,Q25) -> 12 | BU25: 438
A26: 439 | BU26: 439
A27: 440 | BU27: 440
A28: 441 | BU28: 441
A29: 442 | B29: TEJIDO 2 | D29: 3ER TURNO | R29: =$V2 -> DEL 08 AL 14 ENERO 24 | BU29: 442
A30: 443 | E30: L | G30: M | I30: M | K30: J | M30: V | O30: S | V30: 3 | BU30: 443
A31: 444 | B31: 9 | C31: =+C30+1 -> 1 | D31: Bustamante Villegas Osvaldo | E31: 1 | G31: 1 | I31: 1 | K31: 1 | M31: 1 | O31: 1 | Q31: =IF((E31+G31+I31+K31+M31+O31)=6,1,0) -> 1 | R31: 3000 | S31: =+BH31 -> 0 | T31: =+BA31 -> 3000 | U31: =+BP31 -> 0 | V31: =+BG31 -> 0 | W31: =(R31-86.16)/6*E31 -> 485.64 | X31: =$Y$2*E31*Q31 -> 7.18 | Y31: =$Y$2*E31*Q31 -> 7.18 | Z31: =Y31+X31+W31 -> 500 | AB31: =(R31-86.16)/6*G31 -> 485.64 | AC31: =$Y$2*G31*Q31 -> 7.18 | AD31: =$Y$2*G31*Q31 -> 7.18 | AE31: =AD31+AC31+AB31 -> 500 | AG31: =(R31-86.16)/6*I31 -> 485.64 | AH31: =$Y$2*I31*Q31 -> 7.18 | AI31: =$Y$2*I31*Q31 -> 7.18 | AJ31: =AI31+AH31+AG31 -> 500 | AL31: =(R31-86.16)/6*K31 -> 485.64 | AM31: =$Y$2*K31*Q31 -> 7.18 | AN31: =$Y$2*K31*Q31 -> 7.18 | AO31: =AN31+AM31+AL31 -> 500 | AQ31: =(R31-86.16)/6*M31 -> 485.64 | AR31: =$Y$2*M31*Q31 -> 7.18 | AS31: =$Y$2*M31*Q31 -> 7.18 | AT31: =AS31+AR31+AQ31 -> 500 | AV31: =(R31-86.16)/6*O31 -> 485.64 | AW31: =$Y$2*O31*Q31 -> 7.18 | AX31: =$Y$2*O31*Q31 -> 7.18 | AY31: =AX31+AW31+AV31 -> 500 | AZ31: =+AY31+AT31+AO31++AJ31+AE31+Z31 -> 3000 | BA31: =((AZ31-BB31-BC31-BD31-BE31-BF31)+BI31+BJ31+BK31+BL31+BM31+BN31+BO31) -> 3000 | BU31: 444
A32: 445 | B32: 12 | C32: =+C31+1 -> 2 | D32: Diaz Martinez Angela Elizabeth | E32: 1 | G32: 1 | I32: 1 | K32: 1 | M32: 1 | O32: 1 | Q32: =IF((E32+G32+I32+K32+M32+O32)=6,1,0) -> 1 | R32: =IF(Q32=1,1550,850) -> 1550 | S32: =+BH32 -> 0 | T32: =+BA32 -> 2100 | U32: =+BP32 -> 0 | V32: =+BG32 -> BONO+B ASIS | W32: =(R32-86.16)/6*E32 -> 243.97333 | X32: =$Y$2*E32*Q32 -> 7.18 | Y32: =$Y$2*E32*Q32 -> 7.18 | Z32: =Y32+X32+W32 -> 258.33333 | AB32: =(R32-86.16)/6*G32 -> 243.97333 | AC32: =$Y$2*G32*Q32 -> 7.18 | AD32: =$Y$2*G32*Q32 -> 7.18 | AE32: =AD32+AC32+AB32 -> 258.33333 | AG32: =(R32-86.16)/6*I32 -> 243.97333 | AH32: =$Y$2*I32*Q32 -> 7.18 | AI32: =$Y$2*I32*Q32 -> 7.18 | AJ32: =AI32+AH32+AG32 -> 258.33333 | AL32: =(R32-86.16)/6*K32 -> 243.97333 | AM32: =$Y$2*K32*Q32 -> 7.18 | AN32: =$Y$2*K32*Q32 -> 7.18 | AO32: =AN32+AM32+AL32 -> 258.33333 | AQ32: =(R32-86.16)/6*M32 -> 243.97333 | AR32: =$Y$2*M32*Q32 -> 7.18 | AS32: =$Y$2*M32*Q32 -> 7.18 | AT32: =AS32+AR32+AQ32 -> 258.33333 | AV32: =(R32-86.16)/6*O32 -> 243.97333 | AW32: =$Y$2*O32*Q32 -> 7.18 | AX32: =$Y$2*O32*Q32 -> 7.18 | AY32: =AX32+AW32+AV32 -> 258.33333 | AZ32: =+AY32+AT32+AO32++AJ32+AE32+Z32 -> 1550 | BA32: =((AZ32-BB32-BC32-BD32-BE32-BF32)+BI32+BJ32+BK32+BL32+BM32+BN32+BO32) -> 2100 | BG32: BONO+B ASIS | BI32: 300 | BJ32: 250 | BU32: 445
B33: 168 | C33: =+C32+1 -> 3 | D33: Espinoza Ponce Juan Jose | E33: 1 | G33: 1 | I33: 1 | K33: 1 | M33: 1 | O33: 1 | Q33: =IF((E33+G33+I33+K33+M33+O33)=6,1,0) -> 1 | R33: =IF(Q33=1,1550,850) -> 1550 | S33: =+BH33 -> 0 | T33: =+BA33 -> 1800 | U33: =+BP33 -> 0 | V33: =+BG33 -> B ASIS | W33: =(R33-86.16)/6*E33 -> 243.97333 | X33: =$Y$2*E33*Q33 -> 7.18 | Y33: =$Y$2*E33*Q33 -> 7.18 | Z33: =Y33+X33+W33 -> 258.33333 | AB33: =(R33-86.16)/6*G33 -> 243.97333 | AC33: =$Y$2*G33*Q33 -> 7.18 | AD33: =$Y$2*G33*Q33 -> 7.18 | AE33: =AD33+AC33+AB33 -> 258.33333 | AG33: =(R33-86.16)/6*I33 -> 243.97333 | AH33: =$Y$2*I33*Q33 -> 7.18 | AI33: =$Y$2*I33*Q33 -> 7.18 | AJ33: =AI33+AH33+AG33 -> 258.33333 | AL33: =(R33-86.16)/6*K33 -> 243.97333 | AM33: =$Y$2*K33*Q33 -> 7.18 | AN33: =$Y$2*K33*Q33 -> 7.18 | AO33: =AN33+AM33+AL33 -> 258.33333 | AQ33: =(R33-86.16)/6*M33 -> 243.97333 | AR33: =$Y$2*M33*Q33 -> 7.18 | AS33: =$Y$2*M33*Q33 -> 7.18 | AT33: =AS33+AR33+AQ33 -> 258.33333 | AV33: =(R33-86.16)/6*O33 -> 243.97333 | AW33: =$Y$2*O33*Q33 -> 7.18 | AX33: =$Y$2*O33*Q33 -> 7.18 | AY33: =AX33+AW33+AV33 -> 258.33333 | AZ33: =+AY33+AT33+AO33++AJ33+AE33+Z33 -> 1550 | BA33: =((AZ33-BB33-BC33-BD33-BE33-BF33)+BI33+BJ33+BK33+BL33+BM33+BN33+BO33) -> 1800 | BG33: B ASIS | BI33: 100 | BJ33: 150
A34: 445 | B34: 16 | C34: =+C33+1 -> 4 | D34: Favela Saucedo Idalia Azucena | E34: 0 | F34: INC | G34: 0 | H34: INC | I34: 0 | J34: INC | K34: 0 | L34: INC | M34: 0 | N34: INC | O34: 0 | P34: INC | Q34: =IF((E34+G34+I34+K34+M34+O34)=6,1,0) -> 0 | R34: =IF(Q34=1,1550,850) -> 850 | S34: =+BH34 -> 0 | T34: =+BA34 -> 0 | U34: =+BP34 -> 0 | V34: =+BG34 -> 0 | W34: =(R34-86.16)/6*E34 -> 0 | X34: =$Y$2*E34*Q34 -> 0 | Y34: =$Y$2*E34*Q34 -> 0 | Z34: =Y34+X34+W34 -> 0 | AB34: =(R34-86.16)/6*G34 -> 0 | AC34: =$Y$2*G34*Q34 -> 0 | AD34: =$Y$2*G34*Q34 -> 0 | AE34: =AD34+AC34+AB34 -> 0 | AG34: =(R34-86.16)/6*I34 -> 0 | AH34: =$Y$2*I34*Q34 -> 0 | AI34: =$Y$2*I34*Q34 -> 0 | AJ34: =AI34+AH34+AG34 -> 0 | AL34: =(R34-86.16)/6*K34 -> 0 | AM34: =$Y$2*K34*Q34 -> 0 | AN34: =$Y$2*K34*Q34 -> 0 | AO34: =AN34+AM34+AL34 -> 0 | AQ34: =(R34-86.16)/6*M34 -> 0 | AR34: =$Y$2*M34*Q34 -> 0 | AS34: =$Y$2*M34*Q34 -> 0 | AT34: =AS34+AR34+AQ34 -> 0 | AV34: =(R34-86.16)/6*O34 -> 0 | AW34: =$Y$2*O34*Q34 -> 0 | AX34: =$Y$2*O34*Q34 -> 0 | AY34: =AX34+AW34+AV34 -> 0 | AZ34: =+AY34+AT34+AO34++AJ34+AE34+Z34 -> 0 | BA34: =((AZ34-BB34-BC34-BD34-BE34-BF34)+BI34+BJ34+BK34+BL34+BM34+BN34+BO34) -> 0 | BU34: 445
B35: 171 | C35: =+C34+1 -> 5 | D35: Juarez Sifuentes Sandra | E35: 1 | G35: 1 | I35: 1 | K35: 1 | M35: 1 | O35: 0 | P35: F | Q35: =IF((E35+G35+I35+K35+M35+O35)=6,1,0) -> 0 | R35: =IF(Q35=1,1550,850) -> 850 | S35: =+BH35 -> 0 | T35: =+BA35 -> 966.66333 | U35: =+BP35 -> 0 | V35: =+BG35 -> 0 | W35: =(R35-86.16)/6*E35 -> 127.30667 | X35: =$Y$2*E35*Q35 -> 0 | Y35: =$Y$2*E35*Q35 -> 0 | Z35: =Y35+X35+W35 -> 127.30667 | AB35: =(R35-86.16)/6*G35 -> 127.30667 | AC35: =$Y$2*G35*Q35 -> 0 | AD35: =$Y$2*G35*Q35 -> 0 | AE35: =AD35+AC35+AB35 -> 127.30667 | AG35: =(R35-86.16)/6*I35 -> 127.30667 | AH35: =$Y$2*I35*Q35 -> 0 | AI35: =$Y$2*I35*Q35 -> 0 | AJ35: =AI35+AH35+AG35 -> 127.30667 | AL35: =(R35-86.16)/6*K35 -> 127.30667 | AM35: =$Y$2*K35*Q35 -> 0 | AN35: =$Y$2*K35*Q35 -> 0 | AO35: =AN35+AM35+AL35 -> 127.30667 | AQ35: =(R35-86.16)/6*M35 -> 127.30667 | AR35: =$Y$2*M35*Q35 -> 0 | AS35: =$Y$2*M35*Q35 -> 0 | AT35: =AS35+AR35+AQ35 -> 127.30667 | AV35: =(R35-86.16)/6*O35 -> 0 | AW35: =$Y$2*O35*Q35 -> 0 | AX35: =$Y$2*O35*Q35 -> 0 | AY35: =AX35+AW35+AV35 -> 0 | AZ35: =+AY35+AT35+AO35++AJ35+AE35+Z35 -> 636.53333 | BA35: =((AZ35-BB35-BC35-BD35-BE35-BF35)+BI35+BJ35+BK35+BL35+BM35+BN35+BO35) -> 966.66333 | BL35: 330.13
B36: 92 | C36: =+C35+1 -> 6 | D36: Martinez Sifuentes Mariana | E36: 1 | G36: 1 | I36: 1 | K36: 1 | M36: 1 | O36: 1 | Q36: =IF((E36+G36+I36+K36+M36+O36)=6,1,0) -> 1 | R36: =IF(Q36=1,1550,850) -> 1550 | S36: =+BH36 -> 0 | T36: =+BA36 -> 1800 | U36: =+BP36 -> 0 | V36: =+BG36 -> B ASIS | W36: =(R36-86.16)/6*E36 -> 243.97333 | X36: =$Y$2*E36*Q36 -> 7.18 | Y36: =$Y$2*E36*Q36 -> 7.18 | Z36: =Y36+X36+W36 -> 258.33333 | AB36: =(R36-86.16)/6*G36 -> 243.97333 | AC36: =$Y$2*G36*Q36 -> 7.18 | AD36: =$Y$2*G36*Q36 -> 7.18 | AE36: =AD36+AC36+AB36 -> 258.33333 | AG36: =(R36-86.16)/6*I36 -> 243.97333 | AH36: =$Y$2*I36*Q36 -> 7.18 | AI36: =$Y$2*I36*Q36 -> 7.18 | AJ36: =AI36+AH36+AG36 -> 258.33333 | AL36: =(R36-86.16)/6*K36 -> 243.97333 | AM36: =$Y$2*K36*Q36 -> 7.18 | AN36: =$Y$2*K36*Q36 -> 7.18 | AO36: =AN36+AM36+AL36 -> 258.33333 | AQ36: =(R36-86.16)/6*M36 -> 243.97333 | AR36: =$Y$2*M36*Q36 -> 7.18 | AS36: =$Y$2*M36*Q36 -> 7.18 | AT36: =AS36+AR36+AQ36 -> 258.33333 | AV36: =(R36-86.16)/6*O36 -> 243.97333 | AW36: =$Y$2*O36*Q36 -> 7.18 | AX36: =$Y$2*O36*Q36 -> 7.18 | AY36: =AX36+AW36+AV36 -> 258.33333 | AZ36: =+AY36+AT36+AO36++AJ36+AE36+Z36 -> 1550 | BA36: =((AZ36-BB36-BC36-BD36-BE36-BF36)+BI36+BJ36+BK36+BL36+BM36+BN36+BO36) -> 1800 | BG36: B ASIS | BI36: 100 | BJ36: 150
B37: 91 | C37: =+C36+1 -> 7 | D37: Medellin Rodriguez Yesenia Abigail | E37: 1 | G37: 1 | I37: 1 | K37: 1 | M37: 1 | O37: 1 | Q37: =IF((E37+G37+I37+K37+M37+O37)=6,1,0) -> 1 | R37: =IF(Q37=1,1550,850) -> 1550 | S37: =+BH37 -> 0 | T37: =+BA37 -> 1950 | U37: =+BP37 -> 0 | V37: =+BG37 -> BONO+B ASIS | W37: =(R37-86.16)/6*E37 -> 243.97333 | X37: =$Y$2*E37*Q37 -> 7.18 | Y37: =$Y$2*E37*Q37 -> 7.18 | Z37: =Y37+X37+W37 -> 258.33333 | AB37: =(R37-86.16)/6*G37 -> 243.97333 | AC37: =$Y$2*G37*Q37 -> 7.18 | AD37: =$Y$2*G37*Q37 -> 7.18 | AE37: =AD37+AC37+AB37 -> 258.33333 | AG37: =(R37-86.16)/6*I37 -> 243.97333 | AH37: =$Y$2*I37*Q37 -> 7.18 | AI37: =$Y$2*I37*Q37 -> 7.18 | AJ37: =AI37+AH37+AG37 -> 258.33333 | AL37: =(R37-86.16)/6*K37 -> 243.97333 | AM37: =$Y$2*K37*Q37 -> 7.18 | AN37: =$Y$2*K37*Q37 -> 7.18 | AO37: =AN37+AM37+AL37 -> 258.33333 | AQ37: =(R37-86.16)/6*M37 -> 243.97333 | AR37: =$Y$2*M37*Q37 -> 7.18 | AS37: =$Y$2*M37*Q37 -> 7.18 | AT37: =AS37+AR37+AQ37 -> 258.33333 | AV37: =(R37-86.16)/6*O37 -> 243.97333 | AW37: =$Y$2*O37*Q37 -> 7.18 | AX37: =$Y$2*O37*Q37 -> 7.18 | AY37: =AX37+AW37+AV37 -> 258.33333 | AZ37: =+AY37+AT37+AO37++AJ37+AE37+Z37 -> 1550 | BA37: =((AZ37-BB37-BC37-BD37-BE37-BF37)+BI37+BJ37+BK37+BL37+BM37+BN37+BO37) -> 1950 | BG37: BONO+B ASIS | BI37: 250 | BJ37: 150
A38: 448 | B38: 27 | C38: =+C37+1 -> 8 | D38: Minor Flores Adilene | E38: 1 | G38: 1 | I38: 1 | K38: 0 | L38: PSG | M38: 1 | O38: 1 | Q38: =IF((E38+G38+I38+K38+M38+O38)=6,1,0) -> 0 | R38: =IF(Q38=1,1550,850) -> 850 | S38: =+BH38 -> 0 | T38: =+BA38 -> 1508.3333 | U38: =+BP38 -> 0 | V38: =+BG38 -> BONO | W38: =(R38-86.16)/6*E38 -> 127.30667 | X38: =$Y$2*E38*Q38 -> 0 | Y38: =$Y$2*E38*Q38 -> 0 | Z38: =Y38+X38+W38 -> 127.30667 | AB38: =(R38-86.16)/6*G38 -> 127.30667 | AC38: =$Y$2*G38*Q38 -> 0 | AD38: =$Y$2*G38*Q38 -> 0 | AE38: =AD38+AC38+AB38 -> 127.30667 | AG38: =(R38-86.16)/6*I38 -> 127.30667 | AH38: =$Y$2*I38*Q38 -> 0 | AI38: =$Y$2*I38*Q38 -> 0 | AJ38: =AI38+AH38+AG38 -> 127.30667 | AL38: =(R38-86.16)/6*K38 -> 0 | AM38: =$Y$2*K38*Q38 -> 0 | AN38: =$Y$2*K38*Q38 -> 0 | AO38: =AN38+AM38+AL38 -> 0 | AQ38: =(R38-86.16)/6*M38 -> 127.30667 | AR38: =$Y$2*M38*Q38 -> 0 | AS38: =$Y$2*M38*Q38 -> 0 | AT38: =AS38+AR38+AQ38 -> 127.30667 | AV38: =(R38-86.16)/6*O38 -> 127.30667 | AW38: =$Y$2*O38*Q38 -> 0 | AX38: =$Y$2*O38*Q38 -> 0 | AY38: =AX38+AW38+AV38 -> 127.30667 | AZ38: =+AY38+AT38+AO38++AJ38+AE38+Z38 -> 636.53333 | BA38: =((AZ38-BB38-BC38-BD38-BE38-BF38)+BI38+BJ38+BK38+BL38+BM38+BN38+BO38) -> 1508.3333 | BG38: BONO | BI38: 300 | BL38: =271.8+300 -> 571.8 | BU38: 448
A39: 449 | B39: 28 | C39: =+C38+1 -> 9 | D39: Moran Hernandez Raul | E39: 1 | G39: 1 | I39: 1 | K39: 1 | M39: 1 | O39: 1 | Q39: =IF((E39+G39+I39+K39+M39+O39)=6,1,0) -> 1 | R39: =IF(Q39=1,3000,850) -> 3000 | S39: =+BH39 -> 0 | T39: =+BA39 -> 3000 | U39: =+BP39 -> 0 | V39: =+BG39 -> 0 | W39: =(R39-86.16)/6*E39 -> 485.64 | X39: =$Y$2*E39*Q39 -> 7.18 | Y39: =$Y$2*E39*Q39 -> 7.18 | Z39: =Y39+X39+W39 -> 500 | AB39: =(R39-86.16)/6*G39 -> 485.64 | AC39: =$Y$2*G39*Q39 -> 7.18 | AD39: =$Y$2*G39*Q39 -> 7.18 | AE39: =AD39+AC39+AB39 -> 500 | AG39: =(R39-86.16)/6*I39 -> 485.64 | AH39: =$Y$2*I39*Q39 -> 7.18 | AI39: =$Y$2*I39*Q39 -> 7.18 | AJ39: =AI39+AH39+AG39 -> 500 | AL39: =(R39-86.16)/6*K39 -> 485.64 | AM39: =$Y$2*K39*Q39 -> 7.18 | AN39: =$Y$2*K39*Q39 -> 7.18 | AO39: =AN39+AM39+AL39 -> 500 | AQ39: =(R39-86.16)/6*M39 -> 485.64 | AR39: =$Y$2*M39*Q39 -> 7.18 | AS39: =$Y$2*M39*Q39 -> 7.18 | AT39: =AS39+AR39+AQ39 -> 500 | AV39: =(R39-86.16)/6*O39 -> 485.64 | AW39: =$Y$2*O39*Q39 -> 7.18 | AX39: =$Y$2*O39*Q39 -> 7.18 | AY39: =AX39+AW39+AV39 -> 500 | AZ39: =+AY39+AT39+AO39++AJ39+AE39+Z39 -> 3000 | BA39: =((AZ39-BB39-BC39-BD39-BE39-BF39)+BI39+BJ39+BK39+BL39+BM39+BN39+BO39) -> 3000 | BU39: 449
A40: 448 | B40: 170 | C40: =+C39+1 -> 10 | D40: Ochoa Vital Edna Lizeth | E40: 1 | G40: 1 | I40: 1 | K40: 1 | M40: 1 | O40: 1 | Q40: =IF((E40+G40+I40+K40+M40+O40)=6,1,0) -> 1 | R40: =IF(Q40=1,1550,850) -> 1550 | S40: =+BH40 -> 0 | T40: =+BA40 -> 1950 | U40: =+BP40 -> 0 | V40: =+BG40 -> BONO+B ASIS | W40: =(R40-86.16)/6*E40 -> 243.97333 | X40: =$Y$2*E40*Q40 -> 7.18 | Y40: =$Y$2*E40*Q40 -> 7.18 | Z40: =Y40+X40+W40 -> 258.33333 | AB40: =(R40-86.16)/6*G40 -> 243.97333 | AC40: =$Y$2*G40*Q40 -> 7.18 | AD40: =$Y$2*G40*Q40 -> 7.18 | AE40: =AD40+AC40+AB40 -> 258.33333 | AG40: =(R40-86.16)/6*I40 -> 243.97333 | AH40: =$Y$2*I40*Q40 -> 7.18 | AI40: =$Y$2*I40*Q40 -> 7.18 | AJ40: =AI40+AH40+AG40 -> 258.33333 | AL40: =(R40-86.16)/6*K40 -> 243.97333 | AM40: =$Y$2*K40*Q40 -> 7.18 | AN40: =$Y$2*K40*Q40 -> 7.18 | AO40: =AN40+AM40+AL40 -> 258.33333 | AQ40: =(R40-86.16)/6*M40 -> 243.97333 | AR40: =$Y$2*M40*Q40 -> 7.18 | AS40: =$Y$2*M40*Q40 -> 7.18 | AT40: =AS40+AR40+AQ40 -> 258.33333 | AV40: =(R40-86.16)/6*O40 -> 243.97333 | AW40: =$Y$2*O40*Q40 -> 7.18 | AX40: =$Y$2*O40*Q40 -> 7.18 | AY40: =AX40+AW40+AV40 -> 258.33333 | AZ40: =+AY40+AT40+AO40++AJ40+AE40+Z40 -> 1550 | BA40: =((AZ40-BB40-BC40-BD40-BE40-BF40)+BI40+BJ40+BK40+BL40+BM40+BN40+BO40) -> 1950 | BG40: BONO+B ASIS | BI40: 250 | BJ40: 150 | BU40: 448
...

Sheet nom
B1: SEMANA DEL 09 AL 15 DE DICIEMBRE DEL 2024 | Y1: REBAJE POR FALTAS
B2: TEJIDO
B3: TURNO1
B4: Responsable de llenado: | R4: Salario | S4: Bono productividad | T4: Bono de asitencia | U4: Bono extra | V4: Primas, finiquitos, etc | W4: otros | X4: Nominal
B5: # EMP | C5: NOMBRE | D5: PUESTO | E5: L | G5: M | I5: M | K5: J | M5: V | O5: S | Q5: D
B6: 234 | C6: Alvarado Avalos Mayra Daniela | D6: Operador | E6: 1 | G6: 1 | I6: 1 | K6: 1 | M6: 1 | R6: 1550 | S6: 300 | T6: 150 | X6: =+R6+S6+T6+U6+V6+W6 -> 2000
B7: 116 | C7: Antunez Orona Juan Manuel | D7: Creeler | E7: 1 | G7: 1 | I7: 1 | K7: 1 | M7: 1 | R7: 1550 | S7: 300 | T7: 150 | X7: =+R7+S7+T7+U7+V7+W7 -> 2000
A8: =A4+1 -> 1 | B8: 2 | C8: Antunez Requejo Gabriela | D8: Calidad | E8: 1 | G8: 1 | I8: 1 | K8: 1 | M8: 1 | R8: 1550 | S8: 300 | T8: 150 | U8: 300 | X8: =+R8+S8+T8+U8+V8+W8 -> 2300
A9: =A70+1 -> 1 | B9: 6 | C9: Balderas Balderas Myriam Ivet | D9: Lider | E9: 1 | G9: 1 | I9: 1 | K9: 1 | M9: 1 | N9: VAC | R9: 3000 | X9: =+R9+S9+T9+U9+V9+W9 -> 3000
A10: 4 | B10: 9 | C10: Bustamante Villegas Osvaldo | D10: Mecanico | E10: 1 | F10: VAC | G10: 1 | I10: 1 | K10: 1 | M10: 1 | R10: 3000 | U10: 250 | X10: =+R10+S10+T10+U10+V10+W10 -> 3250
A11: =#REF!+1 -> #REF! | B11: 95 | C11: Carrillo Delgado Judith | D11: Operador | E11: 1 | G11: 1 | I11: 1 | K11: 1 | M11: 1 | R11: 1550 | S11: 300 | T11: 150 | W11: 200 | X11: =+R11+S11+T11+U11+V11+W11 -> 2200
A12: =A11+1 -> #REF! | B12: 59 | C12: Castro Viaña Mario Ivan | D12: Mecanico | E12: 1 | G12: 1 | I12: 1 | K12: 1 | M12: 1 | R12: 1550 | S12: 300 | T12: 150 | U12: 500 | X12: =+R12+S12+T12+U12+V12+W12 -> 2500
B13: 12 | C13: Diaz Martinez Angela Elizabeth | D13: calidad | E13: 1 | G13: 1 | I13: 1 | K13: 1 | M13: 1 | R13: 1550 | S13: 300 | T13: 150 | U13: 200 | X13: =+R13+S13+T13+U13+V13+W13 -> 2200
B14: 247 | C14: Gomez Mendoza Ruben Dario | D14: Mecanico | E14: 1 | G14: 1 | I14: 1 | K14: 1 | M14: 1 | R14: 10000 | X14: =+R14+S14+T14+U14+V14+W14 -> 10000
B15: 222 | C15: Hernandez de la Rosa Maria Fernanda | D15: Operador | E15: 1 | G15: 1 | I15: 1 | K15: 1 | M15: 1 | R15: 1550 | S15: 300 | T15: 150 | X15: =+R15+S15+T15+U15+V15+W15 -> 2000
B16: 212 | C16: Hernandez Favela Margarita | D16: operador | E16: 1 | G16: 1 | I16: 1 | K16: 1 | M16: 1 | R16: 1550 | S16: 300 | T16: 150 | X16: =+R16+S16+T16+U16+V16+W16 -> 2000
B17: 236 | C17: Martinez Martinez Maria Azucena | D17: Operador | E17: 1 | G17: 1 | I17: 1 | K17: 1 | M17: 1 | R17: 1550 | S17: 300 | T17: 150 | X17: =+R17+S17+T17+U17+V17+W17 -> 2000
A18: =#REF!+1 -> #REF! | B18: 26 | C18: Medrano Suarez Jose Adolfo | D18: Mecanico | E18: 1 | G18: 1 | I18: 1 | K18: 1 | M18: 1 | R18: 2500 | U18: 200 | X18: =+R18+S18+T18+U18+V18+W18 -> 2700
A19: =#REF!+1 -> #REF! | B19: 28 | C19: Moran Hernandez Raul | D19: Mecanico | E19: 1 | G19: 1 | I19: 1 | K19: 1 | M19: 1 | R19: 5000 | X19: =+R19+S19+T19+U19+V19+W19 -> 5000
B20: 205 | C20: Moreno Favela Sonia Gisela | D20: calidad | E20: 0 | F20: F | G20: 1 | I20: 1 | K20: 1 | M20: 1 | R20: 1240 | U20: 200 | X20: =+R20+S20+T20+U20+V20+W20 -> 1440 | Y20: -310
A21: =#REF!+1 -> #REF! | B21: 169 | C21: Ramirez Requejo Maria Guadalupe | D21: operador | E21: 1 | G21: 1 | I21: 1 | K21: 1 | M21: 1 | R21: 1550 | S21: 300 | T21: 150 | X21: =+R21+S21+T21+U21+V21+W21 -> 2000
B22: 237 | C22: Rodriguez Martinez Jose Antonio | D22: Creeler | E22: 1 | G22: 1 | I22: 1 | K22: 1 | M22: 1 | R22: 1550 | S22: 300 | T22: 150 | X22: =+R22+S22+T22+U22+V22+W22 -> 2000
A23: =#REF!+1 -> #REF! | B23: 146 | C23: Salazar Martinez Yohana Cecilia | D23: Operador | E23: 1 | G23: 1 | I23: 1 | K23: 1 | M23: 1 | R23: 1550 | S23: 300 | T23: 150 | X23: =+R23+S23+T23+U23+V23+W23 -> 2000
B24: 217 | C24: Torres Limones Frida Aurora Shikinkira | D24: Operadora | E24: 1 | G24: 1 | I24: 0 | J24: PSG | K24: 0 | L24: PSG | M24: 0 | N24: PSG | R24: 620 | X24: =+R24+S24+T24+U24+V24+W24 -> 620 | Y24: -930
A25: =A23+1 -> #REF! | B25: 51 | C25: Valenzuela Rosales Jose Miguel | D25: Mecanico | E25: 1 | G25: 1 | H25: VAC | I25: 1 | K25: 1 | M25: 1 | R25: 5000 | U25: 1000 | X25: =+R25+S25+T25+U25+V25+W25 -> 6000
B26: 220 | C26: Vargas Torres Pedro | D26: Creeler | E26: 1 | G26: 1 | I26: 1 | K26: 1 | M26: 1 | R26: 1550 | S26: 250 | T26: 150 | X26: =+R26+S26+T26+U26+V26+W26 -> 1950
B27: 249 | C27: Hernandez Gonzalez Elsa | D27: Operador | E27: 0 | F27: B | G27: 0 | H27: B | I27: 0 | J27: B | K27: 0 | L27: B | M27: 0 | N27: B | X27: 0
E28: =SUM(E6:E27) -> 20 | G28: =SUM(G6:G27) -> 21 | I28: =SUM(I6:I27) -> 20 | K28: =SUM(K6:K27) -> 20 | M28: =SUM(M6:M27) -> 20 | O28: =SUM(O6:O27) -> 0 | R28: =SUM(R6:R27) -> 50510 | S28: =SUM(S6:S27) -> 3850 | T28: =SUM(T6:T27) -> 1950 | U28: =SUM(U6:U27) -> 2650 | V28: =SUM(V6:V27) -> 0 | W28: =SUM(W6:W27) -> 200 | X28: =SUM(X6:X27)-Y24-Y20 -> 60400
X29: =F43-X28 -> 0
D30: NOMINA | E30: EXTRA | F30: TOTAL | K30: L | M30: M | O30: M | Q30: J | S30: V | U30: S
B31: 1 | C31: LIDER | D31: =3000*B31 -> 3000 | E31: 0 | F31: =D31 -> 3000 | V31: PROM
B32: 3 | C32: CALIDAD | D32: =1550*B32 -> 4650 | E32: 0 | F32: =D32 -> 4650 | I32: LIDER | K32: 1 | M32: 1 | O32: 1 | Q32: 1 | S32: 1 | U32: 0 | V32: =AVERAGE(K32,M32,O32,Q32,S32) -> 1
B33: 6 | C33: MECANICO | D33: =3000+1550+10000+2500+5000+5000 -> 27050 | E33: 0 | F33: =D33 -> 27050 | I33: CALIDAD | K33: 2 | M33: 3 | O33: 3 | Q33: 3 | S33: 3 | U33: 0 | V33: =AVERAGE(K33,M33,O33,Q33,S33) -> 2.8
B34: 11 | C34: MANUAL | D34: =1550*B34 -> 17050 | E34: 0 | F34: =D34 -> 17050 | I34: MECANICO | K34: 6 | M34: 6 | O34: 6 | Q34: 6 | S34: 6 | U34: 0 | V34: =AVERAGE(K34,M34,O34,Q34,S34) -> 6
I35: MANUAL | K35: 11 | M35: 11 | O35: 10 | Q35: 10 | S35: 10 | U35: 0 | V35: =AVERAGE(K35,M35,O35,Q35,S35) -> 10.4
B36: =SUM(B31:B35) -> 21 | F36: =SUM(F31:F35) -> 51750 | K36: =SUM(K32:K35) -> 20 | M36: =SUM(M32:M35) -> 21 | O36: =SUM(O32:O35) -> 20 | Q36: =SUM(Q32:Q35) -> 20 | S36: =SUM(S32:S35) -> 20 | U36: =SUM(U32:U35) -> 0 | V36: =AVERAGE(K36,M36,O36,Q36,S36) -> 20.2
E37: BONO | F37: =+S28 -> 3850
E38: BONO ASISTENCIA | F38: =+T28 -> 1950
E39: BONOS EXTRA | F39: =+U28 -> 2650
E40: BONO PRODUCCION EXTRA | F40: =W28 -> 200
...

Sheet Lista 
B2: SEMANA DEL 02 AL 08 DIC DEL 2024 | L2: PARAMETROS A EVALUAR PARA BONO
L3: Deteccion de defectos | M3: limpieza de area | N3: Llenado de formatos | O3: Permisos | P3: Retardos | Q3: BONO
C4: TEJIDO
B5: TURNO1
B6: Responsable de llenado: Myriam Iveth Balderas Balderas
B7: # EMP | C7: NOMBRE | D7: PUESTO | E7: L | F7: M | G7: M | H7: J | I7: V | J7: S | K7: D
A8: 1 | B8: 234 | C8: Alvarado Avalos Mayra Daniela | D8: Operador | E8: A | F8: A | G8: A | H8: A | I8: A
A9: 2 | B9: 116 | C9: Antunez Orona Juan Manuel | D9: Creeler | E9: A | F9: A | G9: A | H9: A | I9: A
A10: 3 | B10: 2 | C10: Antunez Requejo Gabriela | D10: Calidad | E10: A | F10: A | G10: A | H10: A | I10: A
A11: 4 | B11: 6 | C11: Balderas Balderas Myriam Ivet | D11: Lider | E11: A | F11: A | G11: A | H11: A | I11: vac
A12: 5 | B12: 95 | C12: Carrillo Delgado Judith | D12: Operador | E12: A | F12: A | G12: A | H12: A | I12: A
A13: 6 | B13: 12 | C13: Diaz Martinez Angela Elizabeth | D13: calidad | E13: A | F13: A | G13: A | H13: A | I13: A
A14: 7 | B14: 247 | C14: Gomez Mendoza Ruben Dario | D14: Mecanico | E14: A | F14: A | G14: A | H14: A | I14: A
A15: 8 | B15: 222 | C15: Hernandez de la Rosa Maria Fernanda | D15: Operador | E15: A | F15: A | G15: A | H15: A | I15: A
A16: 10 | B16: 236 | C16: Martinez/Martinez Maria Azucena | D16: Operador | E16: A | F16: A | G16: A | H16: A | I16: A
A17: 11 | B17: 26 | C17: Medrano Suarez Jose Adolfo | D17: Mecanico | E17: A | F17: A | G17: A | H17: A | I17: A
A18: 12 | B18: 28 | C18: Moran Hernandez Raul | D18: Mecanico | E18: A | F18: A | G18: A | H18: A | I18: A
A19: 13 | B19: 146 | C19: Salazar Martinez Yohana Cecilia | D19: Operador | E19: A | F19: A | G19: A | H19: A | I19: A
... A22: 16 | B22: 220 | C22: Vargas Torres Pedro | D22: Creeler | E22: A | F22: A | G22: A | H22: A | I22: A
B24: =+B2 -> SEMANA DEL 02 AL 08 DIC DEL 2024 | L24: PARAMETROS A EVALUAR PARA BONO
L25: Deteccion de defectos | M25: limpieza de area | N25: Llenado de formatos | O25: Permisos | P25: Retardos | Q25: BONO
C26: TEJIDO
B27: TURNO1
B28: Responsable de llenado: Myriam Iveth Balderas Balderas
B29: # EMP | C29: NOMBRE | D29: PUESTO | E29: L | F29: M | G29: M | H29: J | I29: V | J29: S | K29: D
A30: 1 | B30: 147 | C30: Alaniz Mayorga Yulissa | D30: OPERADOR | E30: INC | F30: INC | G30: INC | H30: INC | I30: INC | J30: INC
A31: 2 | B31: 132 | C31: Alvarado Ojeda Dulce Violeta | D31: operador | E31: A | F31: A | G31: A | H31: A | I31: A
A32: 3 | B32: 208 | C32: Avalos Villegas Chayanne | D32: Mecanico | E32: A | F32: A | G32: A | H32: A | I32: A
A33: 4 | B33: 7 | C33: Beberaje Cruz Ramon Humberto | D33: Mecanico | E33: A | F33: A | G33: A | H33: A | I33: A
A34: 5 | B34: 225 | C34: Flores Ortiz Elizabeth | D34: operador | E34: B | F34: B | G34: B | H34: B | I34: B
A35: 6 | B35: 70 | C35: Gonzales Lopez Violeta | D35: OPERADOR | E35: SAN | F35: SAN | G35: A | H35: A | I35: A
A36: 7 | B36: 212 | C36: Hernandez Favela Margarita | D36: operador | E36: A | F36: A | G36: A | H36: A | I36: A
A37: 8 | B37: 181 | C37: Hernandez Garcia Santa Maria Magdalena | D37: operador | E37: A | F37: A | G37: A | H37: A | I37: A
A38: 9 | B38: 223 | C38: Martinez Hernandez Irvin Adolfo | D38: creler | E38: SAN | F38: SAN | G38: A | H38: A | I38: A
A39: 10 | B39: 204 | C39: Mendez Reyes Yesica Ivon | D39: calidad | E39: B | F39: B | G39: B | H39: B | I39: B
A40: 11 | B40: 205 | C40: Moreno Favela Sonia Gisela | D40: calidad | E40: A | F40: A | G40: A | H40: A | I40: F
A41: 12 | B41: 169 | C41: Ramirez Requejo Maria Guadalupe | D41: Operador | E41: A | F41: A | G41: A | H41: A | I41: A
A42: 13 | B42: 207 | C42: Silva Moreno Maria guadalupe | D42: operadora | E42: A | F42: A | G42: A | H42: A | I42: A
A43: 14 | B43: 228 | C43: Tostado Sifuentes Haxel Rodrigo | D43: creler | E43: A | F43: A | G43: A | H43: A | I43: SAN
B47: =+B2 -> SEMANA DEL 02 AL 08 DIC DEL 2024 | L47: PARAMETROS A EVALUAR PARA BONO
...

Sheet resumen rh
A6: =+nom!B1 -> SEMANA DEL 09 AL 15 DE DICIEMBRE DEL 2024
A7: =+AVERAGE(C7,E7,G7,I7,K7,M7) -> 16.833333 | C7: =+nom!K36 -> 20 | E7: =+nom!M36 -> 21 | G7: =+nom!O36 -> 20 | I7: =+nom!Q36 -> 20 | K7: =+nom!S36 -> 20 | M7: =+nom!U36 -> 0 | N7: TEJIDO
A8: =+AVERAGE(C8,E8,G8,I8,K8) -> 0 | C8: =+nom!E51 -> 0 | E8: =+nom!G51 -> 0 | G8: =+nom!I51 -> 0 | I8: =+nom!K51 -> 0 | K8: =+nom!M51 -> 0 | M8: =+nom!O51 -> 0 | N8: TEJIDO 2
A9: =+AVERAGE(C9,E9,G9,I9,K9) -> 14.8 | C9: =+nom!K98 -> 15 | E9: =+nom!M98 -> 15 | G9: =+nom!O98 -> 15 | I9: =+nom!Q98 -> 14 | K9: =+nom!S98 -> 15 | M9: =+nom!U98 -> 0 | N9: TEJIDO 3
A10: =+AVERAGE(C10,E10,G10,I10,K10,M10) -> 6 | C10: =+nom!K199 -> 6 | E10: =+nom!M199 -> 6 | G10: =+nom!O199 -> 6 | I10: =+nom!Q199 -> 6 | K10: =+nom!S199 -> 6 | M10: =+nom!U199 -> 6 | N10: PUÑO
A11: =+AVERAGE(C11,E11,G11,I11,K11,M11) -> 7.6666667 | C11: =+nom!K232 -> 7 | E11: =+nom!M232 -> 7 | G11: =+nom!O232 -> 8 | I11: =+nom!Q232 -> 8 | K11: =+nom!S232 -> 8 | M11: =+nom!U232 -> 8 | N11: PUÑO2
A12: =+AVERAGE(C12,E12,G12,I12,K12) -> 4.6 | C12: =+nom!K259 -> 4 | E12: =+nom!M259 -> 4 | G12: =+nom!O259 -> 5 | I12: =+nom!Q259 -> 5 | K12: =+nom!S259 -> 5 | M12: =+nom!U259 -> 0 | N12: PUÑO3
A13: =+AVERAGE(C13,E13,G13,I13,K13) -> 6.8 | C13: =+nom!K129 -> 7 | E13: =+nom!M129 -> 6 | G13: =+nom!O129 -> 7 | I13: =+nom!Q129 -> 7 | K13: =+nom!S129 -> 7 | M13: =+nom!U129 -> 0 | N13: AE
A14: =+AVERAGE(C14,E14,G14,I14,K14) -> 0 | C14: =+nom!K150 -> 0 | E14: =+nom!M150 -> 0 | G14: =+nom!O150 -> 0 | I14: =+nom!Q150 -> 0 | K14: =+nom!S150 -> 0 | M14: =+nom!U150 -> 0 | N14: AE 2
A15: =+AVERAGE(C15,E15,G15,I15,K15) -> 4.8 | C15: =+nom!K174 -> 5 | E15: =+nom!M174 -> 5 | G15: =+nom!O174 -> 5 | I15: =+nom!Q174 -> 5 | K15: =+nom!S174 -> 4 | M15: =+nom!U174 -> 0 | N15: AE 3
A16: =+AVERAGE(C16,E16,G16,I16,K16) -> 11.4 | C16: =+nom!L298 -> 12 | E16: =+nom!N298 -> 12 | G16: =+nom!P298 -> 12 | I16: =+nom!R298 -> 11 | K16: =+nom!T298 -> 10 | M16: 0 | N16: TEJIDO LEON
A17: =+AVERAGE(C17,E17,G17,I17,K17) -> 1 | C17: =+nom!E309 -> 1 | E17: =+nom!G309 -> 1 | G17: =+nom!I309 -> 1 | I17: =+nom!K309 -> 1 | K17: =+nom!M309 -> 1 | M17: =+nom!O309 -> 1 | N17: APOYO LG
A19: =+AVERAGE(C19,E19,G19,I19,K19) -> 77.2 | C19: =SUM(C7:C18) -> 77 | E19: =SUM(E7:E18) -> 77 | G19: =SUM(G7:G18) -> 79 | I19: =SUM(I7:I18) -> 77 | K19: =SUM(K7:K18) -> 76 | M19: =SUM(M7:M18) -> 15 | N19: TOT

Sheet CHECADAS
A1: Nominas
A2: N+A2:N48umero | B2: NombreCompleto | C2: FechaInicio | D2: FechaFin | E2: L.Entrada | F2: L.Salida | G2: MA.Entrada | H2: MA.Salida | I2: MI.Entrada | J2: MI.Salida | K2: J.Entrada | L2: J.Salida | M2: V.Entrada | N2: V.Salida | O2: S.Entrada | P2: S.Salida | Q2: D.Entrada | R2: D.Salida
A3: 107 | B3: SAMUEL CHAVARRIA MACHADO | C3: 2024-12-09 | D3: 2024-12-15 | E3: 15:31:00 | F3: 0.98003472 | G3: 15:33:00 | H3: 0.98616898 | I3: 15:22:00 | J3: 0.97959491 | K3: 15:28:00 | L3: 11:35:36 p. m. | M3: 15:26:00 | N3: 0.98320602 | O3: 15:29:00 | P3: 08:33:01 p. m.
A4: 111 | B4: GLADIS NAYELI VIAÑA DOMINGUEZ | C4: 2024-12-09 | D4: 2024-12-15 | E4: 07:26:00 | F4: 15:31:00 | G4: 07:29:00 | H4: 15:31:00 | I4: 07:29:00 | J4: 03:29:14 p. m. | K4: 07:32:00 | L4: 15:34:00 | M4: 07:32:00 | N4: 15:30:00 | O4: 07:28:00
A5: 116 | B5: JUAN MANUEL ANTUNEZ ORONA | C5: 2024-12-09 | D5: 2024-12-15 | E5: 07:29:00 | F5: 17:02:00 | G5: 07:36:00 | H5: 17:02:00 | I5: 07:31:00 | J5: 17:01:00 | K5: 07:31:00 | L5: 16:59:00 | M5: 07:34:00 | N5: 17:00:00
A6: 12 | B6: ANGELA ELIZABETH DIAZ MARTINEZ | C6: 2024-12-09 | D6: 2024-12-15 | E6: 07:17:00 | F6: 0.70957176 | G6: 0.30185185 | H6: 0.70961806 | I6: 07:18:00 | J6: 0.70797454 | K6: 07:27:00 | L6: 04:57:20 p. m. | M6: 0.30197917 | N6: 04:55:13 p. m.
A7: 135 | B7: SUGEY MARISOL MARTINEZ ROSALES | C7: 2024-12-09 | D7: 2024-12-15 | E7: 11:32:58 p. m. | F7: 07:33:36 a. m. | G7: 0.98303241 | H7: 07:33:49 a. m. | I7: 0.98252315 | J7: 0.31326389 | K7: 0.98013889 | L7: 0.31391204 | M7: 11:38:13 p. m. | N7: 0.31340278
A8: 14 | B8: MIGUEL ANGEL ESQUIVEL PICON | C8: 2024-12-09 | D8: 2024-12-15 | E8: 0.96398148 | F8: 07:32:00 | G8: 0.96053241 | H8: 07:32:00 | I8: 0.96232639 | J8: 07:36:00 | K8: 0.96474537 | L8: 07:32:00 | M8: 11:07:30 p. m. | N8: 07:31:00
A9: 141 | B9: MA. ISABEL VARGAS MENDEZ | C9: 2024-12-09 | D9: 2024-12-15 | E9: 07:25:00 | F9: 17:00:00 | G9: 07:25:00 | H9: 17:02:00 | I9: 07:25:00 | J9: 17:00:00 | K9: 07:25:00 | L9: 17:01:00 | M9: 07:25:00 | N9: 17:00:00
A10: 1446 | B10: SAUL BAUTISTA REVUELTAS | C10: 2024-12-09 | D10: 2024-12-15
A11: 146 | B11: YOHANA CECILIA SALAZAR MARTINEZ | C11: 2024-12-09 | D11: 2024-12-15 | E11: 07:25:00 | F11: 0.70924769 | G11: 07:23:00 | H11: 0.70983796 | I11: 07:21:00 | J11: 05:00:59 p. m. | K11: 07:24:00 | L11: 0.70633102 | M11: 07:22:00 | N11: 0.70596065
A12: 147 | B12: YULISSA ALANIZ MAYORGA | C12: 2024-12-09 | D12: 2024-12-15 | E12: inc | G12: inc | I12: inc | K12: inc | M12: inc
A13: 158 | B13: JOSE ALBERTO CABALLERO COYOC | C13: 2024-12-09 | D13: 2024-12-15 | E13: 0.98157407 | F13: 07:32:00 | G13: 0.97608796 | I13: 0.97109954 | J13: 07:33:00 | K13: 0.97957176 | L13: 07:34:00 | M13: 0.97413194 | N13: 07:30:00
A14: 159 | B14: HERBER ANTONY PEREZ SUAREZ | C14: 2024-12-09 | D14: 2024-12-15 | E14: 0.96412037 | F14: 07:30:00 | G14: 0.96040509 | H14: 07:34:00 | I14: 0.96165509 | J14: 07:39:00 | K14: 0.96366898 | L14: 07:38:00 | M14: 11:05:57 p. m. | N14: 07:30:00
A15: 165 | B15: DIEGO FRANCO ALATORRE | C15: 2024-12-09 | D15: 2024-12-15
A16: 166 | B16: ACACIA ENRIQUEZ GUTIERREZ | C16: 2024-12-09 | D16: 2024-12-15 | E16: 07:25:00 | F16: 05:00:39 p. m. | G16: 07:25:00 | H16: 0.7100463 | I16: 07:25:00 | J16: 05:00:48 p. m. | K16: 07:25:00 | L16: 05:01:37 p. m. | M16: 07:25:00 | N16: 0.70869213
A17: 169 | B17: MARIA GUADALUPE RAMIREZ REQUEJO | C17: 2024-12-09 | D17: 2024-12-15 | E17: 07:32:00 | F17: 17:02:00 | G17: 07:36:00 | H17: 17:02:00 | I17: 07:30:00 | J17: 17:00:00 | K17: 07:26:00 | L17: 0.70795139 | M17: 07:27:00 | N17: 17:00:00
A18: 172 | B18: MARIA ELENA HERNANDEZ CAMPISTA | C18: 2024-12-09 | D18: 2024-12-15 | E18: 0.2852662 | F18: 0.68082176 | G18: 06:50:11 a. m. | H18: 04:21:10 p. m. | I18: 06:47:03 a. m. | J18: 0.68109954 | K18: vac | M18: vac
A19: 181 | B19: SANTA MARIA MAGDALENA HERNANDEZ GARCIA | C19: 2024-12-09 | D19: 2024-12-15 | E19: 11:19:22 p. m. | F19: 07:30:00 | G19: 11:25:27 p. m. | H19: 07:21:00 | I19: 0.97550926 | J19: 07:31:00 | K19: 0.97516204 | L19: 07:25:00 | M19: 0.97255787 | N19: 07:30:00
A20: 19 | B20: ELIZABETH GARCIA NUÑEZ | C20: 2024-12-09 | D20: 2024-12-15 | E20: 07:32:00 | F20: 17:01:00 | G20: 07:31:00 | H20: 17:03:00 | I20: 07:34:00 | J20: 17:01:00 | K20: 07:37:00 | L20: 17:03:00
A21: 195 | B21: PERLA NOHEMI FLORES ORTIZ | C21: 2024-12-09 | D21: 2024-12-15 | E21: 0.31259259 | F21: 0.70931713 | G21: falta | I21: 0.31758102 | J21: 0.70891204 | K21: 0.31949074 | L21: 0.70987269 | M21: 0.31890046 | N21: 0.71012731
A22: 2 | B22: GABRIELA ANTUNEZ REQUEJO | C22: 2024-12-09 | D22: 2024-12-15 | E22: 07:31:00 | G22: 07:30:00 | H22: 0.71023148 | I22: 07:28:00 | J22: 05:01:42 p. m. | K22: 07:26:00 | L22: 05:02:16 p. m. | M22: 07:32:00 | N22: 0.71017361
A23: 205 | B23: SONIA GISELA MORENO FAVELA | C23: 2024-12-09 | D23: 2024-12-15 | E23: falta | G23: 0.31716435 | H23: 0.71064815 | I23: 07:35:58 a. m. | J23: 0.70940972 | L23: 0.70773148 | M23: 07:29:30 a. m. | N23: 03:32:02 p. m.
A24: 207 | B24: MARIA GUADALUPE SILVA MORENO | C24: 2024-12-09 | D24: 2024-12-15 | E24: 0.64784722 | F24: 11:31:43 p. m. | G24: 0.64528935 | H24: 11:32:46 p. m. | I24: 03:24:40 p. m. | J24: 11:30:58 p. m. | K24: 0.64511574 | L24: 0.98184028 | M24: 0.64704861 | N24: 0.97966435 | O24: 03:32:17 p. m. | P24: 0.85719907
A25: 210 | B25: NANCY LORENA PADILLA ARMIJO | C25: 2024-12-09 | D25: 2024-12-15 | E25: 0.98703704 | F25: 0.31706019 | G25: 11:39:51 p. m. | H25: 0.32371528 | I25: 11:37:08 p. m. | J25: 07:35:15 a. m. | K25: 0.98784722 | L25: 0.31966435 | M25: 0.98813657 | N25: 0.31287037
A26: 212 | B26: MARGARITA HERNANDEZ FAVELA | C26: 2024-12-09 | D26: 2024-12-15 | E26: 0.31071759 | F26: 05:00:24 p. m. | G26: 0.3140625 | H26: 05:01:56 p. m. | I26: 0.31163194 | J26: 0.70916667 | K26: 0.31234954 | L26: 0.70777778 | M26: 07:26:55 a. m. | N26: 0.70887731
A27: 214 | B27: LEIDY DANIELA GRESS PADILLA | C27: 2024-12-09 | D27: 2024-12-15 | E27: 0.97842593 | F27: 07:31:00 | G27: 0.97474537 | H27: 07:32:00 | I27: 11:23:05 p. m. | J27: 07:31:00 | K27: 0.97596065 | L27: 07:31:00 | M27: 0.97392361 | N27: 07:30:00
A28: 215 | B28: HILDA YUDITH HOLGUIN SALAS | C28: 2024-12-09 | D28: 2024-12-15 | G28: 11:27:59 p. m. | H28: 07:31:00 | M28: 0.9791088 | N28: 07:30:00
A29: 216 | B29: JAVIER ARMANDO ANTUNEZ ROMERO | C29: 2024-12-09 | D29: 2024-12-15 | E29: 07:46:00 | F29: 01:06:02 p. m. | G29: 07:20:00 | H29: 05:39:35 p. m. | I29: 07:48:00 | J29: 0.70979167 | K29: 07:37:00 | L29: 03:31:25 p. m. | M29: falta
A30: 217 | B30: FRIDA AURORA TORRES LIMONES | C30: 2024-12-09 | D30: 2024-12-15 | E30: 07:11:28 a. m. | F30: 0.70868056 | G30: 0.29376157 | H30: 0.62751157 | I30: psg | K30: psg | M30: psg
A31: 220 | B31: PEDRO VARGAS TORRES | C31: 2024-12-09 | D31: 2024-12-15 | E31: 07:28:00 | G31: 07:29:00 | H31: 05:02:36 p. m. | I31: 07:30:00 | J31: 0.70954861 | K31: 07:29:00 | L31: 04:59:36 p. m. | M31: 07:30:00 | N31: 0.70883102
A32: 222 | B32: MARIA FERNANDA HERNANDEZ DE LA ROSA | C32: 2024-12-09 | D32: 2024-12-15 | E32: 07:38:00 | F32: 0.70865741 | G32: 07:37:00 | H32: 0.70971065 | I32: 07:38:00 | J32: 0.70975694 | K32: 07:21:00 | L32: 04:59:15 p. m. | M32: 07:22:00 | N32: 0.70877315
A33: 223 | B33: IRVIN ADOLFO MARTINEZ HERNANDEZ | C33: 2024-12-09 | D33: 2024-12-15 | E33: sanc | G33: san | I33: 0.97444444 | J33: 07:37:08 a. m. | K33: 11:24:10 p. m. | L33: 0.31252315 | M33: 0.97261574 | N33: 0.31376157
A34: 226 | B34: JOSE URIEL MORENO MARTINEZ | C34: 2024-12-09 | D34: 2024-12-15 | E34: 15:31:00 | F34: 0.98065972 | G34: 15:34:00 | H34: 0.98079861 | I34: 15:22:00 | J34: 0.97987269 | K34: 15:29:00 | L34: 0.97987269 | M34: 15:26:00 | N34: 0.98028935 | O34: 15:30:00 | P34: 0.85783565
A35: 227 | B35: JOSE LUIS MARTINEZ ROSALES | C35: 2024-12-09 | D35: 2024-12-15 | E35: 11:33:01 p. m. | F35: 07:32:00 | G35: 0.98306713 | H35: 07:33:00 | I35: 0.98244213 | J35: 07:31:00 | K35: 0.98017361 | L35: 07:32:00 | M35: 0.98421296 | N35: 07:31:00 | O35: 0.98163194
A36: 228 | B36: HAXEL RODRIGO TOSTADO SIFUENTES | C36: 2024-12-09 | D36: 2024-12-15 | E36: 0.97766204 | F36: 0.31334491 | G36: 0.9828125 | H36: 0.31461806 | I36: 11:30:40 p. m. | J36: 0.31315972 | K36: 11:27:24 p. m. | L36: 0.31489583 | M36: san
A37: 230 | B37: PRINCE ANAIS LLAMAS PEREZ | C37: 2024-12-09 | D37: 2024-12-15 | E37: 0.30128472 | F37: 0.64645833 | G37: 07:20:00 | H37: 0.64643519 | I37: 07:16:00 | J37: 03:30:09 p. m. | K37: 07:15:00 | L37: 0.69238426 | M37: 07:21:00 | N37: 0.64658565 | O37: 07:45:00 | P37: 0.64797454
A38: 231 | B38: EFRAIN SOLIS CARRANZA | C38: 2024-12-09 | D38: 2024-12-15 | E38: 0.99008102 | F38: 07:31:00 | G38: 0.98799769 | H38: 07:33:00 | I38: 0.99005787 | J38: 07:30:00 | K38: 0.98708333 | L38: 07:33:00 | M38: 0.0023263889 | N38: 07:30:00
A39: 232 | B39: NORMA CECILIA GONZALEZ OJEDA | C39: 2024-12-09 | D39: | | E39: 15:31:00 | F39: 0.98059028 | G39: 15:29:00 | H39: 0.98113426 | I39: 15:24:00 | J39: 0.97954861 | K39: 15:28:00 | L39: 0.98179398 | M39: 15:31:00 | N39: 0.97950231 | O39: 15:32:00 | P39: 0.85773148
A40: 237 | B40: JOSE ANTONIO RODRIGUEZ MARTINEZ | C40: 2024-12-09 | D40: 2024-12-15 | E40: 0.31519676 | F40: 0.70946759 | G40: 0.31231481 | H40: 05:02:40 p. m. | I40: 0.31422454 | J40: 0.70927083 | K40: 07:29:44 a. m. | L40: 07:32:00 | N40: 0.70857639
...

Sheet REPORTE
A1: Date | B1: Device ID | C1: Device | D1: User Group | E1: User | F1: Event
A2: 45641.979 | B2: 542361075 | C2: FaceStation 2 542361075 (192.168.50.204) | D2: All Users | E2: 45 | F2: 1:N authentication succeeded (Face)
A3: 45641.967 | B3: 542361075 | C3: FaceStation 2 542361075 (192.168.50.204) | D3: All Users | E3: 94 | F3: 1:N authentication succeeded (Face)
A4: 45641.757 | B4: 542361075 | C4: FaceStation 2 542361075 (192.168.50.204) | D4: All Users | E4: 34 | F4: 1:N authentication succeeded (Face)
A5: 45641.754 | B5: 542361075 | C5: FaceStation 2 542361075 (192.168.50.204) | F5: DHCP connected
A6: 45641.752 | B6: 542361075 | C6: FaceStation 2 542361075 (192.168.50.204) | F6: DHCP connected
A7: 45641.752 | B7: 542361075 | C7: FaceStation 2 542361075 (192.168.50.204) | F7: Network connected
A8: 45641.752 | B8: 542361075 | C8: FaceStation 2 542361075 (192.168.50.204) | F8: Network disconnected
A9: 45641.752 | B9: 542361075 | C9: FaceStation 2 542361075 (192.168.50.204) | F9: Network connected
A10: 45641.752 | B10: 542361075 | C10: FaceStation 2 542361075 (192.168.50.204) | F10: Network disconnected
A11: 45641.752 | B11: 542361075 | C11: FaceStation 2 542361075 (192.168.50.204) | F11: Tamper off
A12: 45641.752 | B12: 542361075 | C12: FaceStation 2 542361075 (192.168.50.204) | F12: DHCP connected
A13: 45641.752 | B13: 542361075 | C13: FaceStation 2 542361075 (192.168.50.204) | F13: Device started
A14: 45641.752 | B14: 542361075 | C14: FaceStation 2 542361075 (192.168.50.204) | F14: Network connected
A15: 45641.746 | B15: 542361075 | C15: FaceStation 2 542361075 (192.168.50.204) | F15: Tamper off
A16: 45641.746 | B16: 542361075 | C16: FaceStation 2 542361075 (192.168.50.204) | F16: DHCP connected
... A18: 45641.746 | B18: 542361075 | C18: FaceStation 2 542361075 (192.168.50.204) | F18: Network connected
A19: 45641.688 | B19: 542361075 | C19: FaceStation 2 542361075 (192.168.50.204) | D19: All Users | E19: 34 | F19: 1:N authentication succeeded (Face)
A20: 45641.556 | B20: 542361075 | C20: FaceStation 2 542361075 (192.168.50.204) | F20: Tamper off
A21: 45641.556 | B21: 542361075 | C21: FaceStation 2 542361075 (192.168.50.204) | F21: DHCP connected
A22: 45641.556 | B22: 542361075 | C22: FaceStation 2 542361075 (192.168.50.204) | F22: Device started
A23: 45641.556 | B23: 542361075 | C23: FaceStation 2 542361075 (192.168.50.204) | F23: Network connected
A24: 45641.504 | B24: 542361075 | C24: FaceStation 2 542361075 (192.168.50.204) | D24: All Users | E24: 63 | F24: 1:N authentication succeeded (Face)
A25: 45641.326 | B25: 542361075 | C25: FaceStation 2 542361075 (192.168.50.204) | D25: All Users | E25: 35 | F25: 1:N authentication succeeded (Face)
A26: 45641.324 | B26: 542361075 | C26: FaceStation 2 542361075 (192.168.50.204) | D26: All Users | E26: 94 | F26: 1:N authentication succeeded (Face)
A27: 45641.324 | B27: 542361075 | C27: FaceStation 2 542361075 (192.168.50.204) | D27: All Users | E27: 45 | F27: 1:N authentication succeeded (Face)
A28: 45641.316 | B28: 542361075 | C28: FaceStation 2 542361075 (192.168.50.204) | D28: All Users | E28: 63 | F28: 1:N authentication succeeded (Face)
A29: 45641.315 | B29: 542361075 | C29: FaceStation 2 542361075 (192.168.50.204) | D29: All Users | E29: 227 | F29: 1:N authentication succeeded (Face)
A30: 45641.168 | B30: 542361075 | C30: FaceStation 2 542361075 (192.168.50.204) | D30: All Users | E30: 94 | F30: 1:N authentication succeeded (Face)
A31: 45641.147 | B31: 542361075 | C31: FaceStation 2 542361075 (192.168.50.204) | D31: All Users | E31: 94 | F31: 1:N authentication succeeded (Face)
A32: 45641.145 | B32: 542361075 | C32: FaceStation 2 542361075 (192.168.50.204) | D32: All Users | E32: 227 | F32: 1:N authentication succeeded (Face)
A33: 45641.123 | B33: 542361075 | C33: FaceStation 2 542361075 (192.168.50.204) | D33: All Users | E33: 227 | F33: 1:N authentication succeeded (Face)
A34: 45641.015 | B34: 542361075 | C34: FaceStation 2 542361075 (192.168.50.204) | D34: All Users | E34: 94 | F34: 1:N authentication succeeded (Face)
A35: 45640.982 | B35: 542361075 | C35: FaceStation 2 542361075 (192.168.50.204) | D35: All Users | E35: 227 | F35: 1:N authentication succeeded (Face)
... A44: 45640.856 | B44: 542361075 | C44: FaceStation 2 542361075 (192.168.50.204) | D44: All Users | E44: 107 | F44: 1:N authentication succeeded (Face)
A45: 45640.797 | B45: 542361075 | C45: FaceStation 2 542361075 (192.168.50.204) | F45: DHCP connected
A46: 45640.794 | B46: 542361075 | C46: FaceStation 2 542361075 (192.168.50.204) | F46: Network connected
A47: 45640.794 | B47: 542361075 | C47: FaceStation 2 542361075 (192.168.50.204) | F47: Network disconnected
A48: 45640.729 | B48: 542361075 | C48: FaceStation 2 542361075 (192.168.50.204) | D48: All Users | E48: 63 | F48: 1:N authentication succeeded (Face)
A49: 45640.65 | B49: 542361075 | C49: FaceStation 2 542361075 (192.168.50.204) | D49: All Users | E49: 69 | F49: 1:N authentication succeeded (Face)
...
