Workbook

Sheet NOMINA TEJIDO 
A1: 1 | AA1: MARTES 06/03 | AF1: MIERCOLES 07/03 | AK1: JUEVES 08/03 | AP1: VIERNES 09/03 | AU1: SABADO 10/03 | BU1: 1
A2: 2 | B2: TEJIDO | T2: SUELDO ESTIMADO FALTA SOLO RELOJ | U2: BONO | V2: DEL 08 AL 14 ENERO 24 | X2: 7.18 | Y2: 7.18 | BA2: 0 | BU2: 2
A3: 3 | E3: L | G3: M | I3: M | K3: J | M3: V | O3: S | R3: COSTOS | V3: 0 | W3: NOMINA | X3: PXP | Y3: PXA | Z3: TOTAL | AA3: INC | AB3: NOMINA | AC3: PXP | AD3: PXA | AE3: TOTAL | AF3: INC | AG3: NOMINA | AH3: PXP | AI3: PXA | AJ3: TOTAL | AK3: INC | AL3: NOMINA | AM3: PXP | AN3: PXA | AO3: TOTAL | AP3: INC | AQ3: NOMINA | AR3: PXP | AS3: PXA | AT3: TOTAL | AU3: INC | AV3: NOMINA | AW3: PXP | AX3: PXA | AY3: TOTAL | BB3: CB | BC3: FP | BD3: L | BE3: R | BI3: INC | BJ3: B ASISTENCIA | BK3: T EXT | BM3: PRIMAS | BN3: PAGO EXTRA | BQ3: 3 | BR3: =0.167*4+4 -> 4.668 | BU3: 3
B4: 164 | C4: =+C3+1 -> 1 | E4: 1 | G4: 1 | I4: 1 | K4: 1 | M4: 1 | O4: 1 | Q4: =IF((E4+G4+I4+K4+M4+O4)=6,1,0) -> 1 | R4: =IF(Q4=1,1550,850) -> 1550 | S4: =+BH4 -> 0 | T4: =+BA4 -> 929 | U4: =+BP4 -> 0 | V4: =+BG4 -> BONO+ B ASIS | W4: =(R4-86.16)/6*E4 -> 243.97333 | X4: =$Y$2*E4*Q4 -> 7.18 | Y4: =$Y$2*E4*Q4 -> 7.18 | Z4: =Y4+X4+W4 -> 258.33333 | AB4: =(R4-86.16)/6*G4 -> 243.97333 | AC4: =$Y$2*G4*Q4 -> 7.18 | AD4: =$Y$2*G4*Q4 -> 7.18 | AE4: =AD4+AC4+AB4 -> 258.33333 | AG4: =(R4-86.16)/6*I4 -> 243.97333 | AH4: =$Y$2*I4*Q4 -> 7.18 | AI4: =$Y$2*I4*Q4 -> 7.18 | AJ4: =AI4+AH4+AG4 -> 258.33333 | AL4: =(R4-86.16)/6*K4 -> 243.97333 | AM4: =$Y$2*K4*Q4 -> 7.18 | AN4: =$Y$2*K4*Q4 -> 7.18 | AO4: =AN4+AM4+AL4 -> 258.33333 | AQ4: =(R4-86.16)/6*M4 -> 243.97333 | AR4: =$Y$2*M4*Q4 -> 7.18 | AS4: =$Y$2*M4*Q4 -> 7.18 | AT4: =AS4+AR4+AQ4 -> 258.33333 | AV4: =(R4-86.16)/6*O4 -> 243.97333 | AW4: =$Y$2*O4*Q4 -> 7.18 | AX4: =$Y$2*O4*Q4 -> 7.18 | AY4: =AX4+AW4+AV4 -> 258.33333 | AZ4: =+AY4+AT4+AO4++AJ4+AE4+Z4 -> 1550 | BA4: 929 | BG4: BONO+ B ASIS
A5: 420 | B5: 2 | C5: =+C4+1 -> 2 | D5: Antunez Requejo Gabriela | E5: 1 | G5: 1 | I5: 1 | K5: 1 | M5: 1 | O5: 1 | Q5: =IF((E5+G5+I5+K5+M5+O5)=6,1,0) -> 1 | R5: =IF(Q5=1,1550,850) -> 1550 | S5: =+BH5 -> 0 | T5: =+BA5 -> 2100 | U5: =+BP5 -> 0 | V5: =+BG5 -> BONO+ B ASIS | W5: =(R5-86.16)/6*E5 -> 243.97333 | X5: =$Y$2*E5*Q5 -> 7.18 | Y5: =$Y$2*E5*Q5 -> 7.18 | Z5: =Y5+X5+W5 -> 258.33333 | AB5: =(R5-86.16)/6*G5 -> 243.97333 | AC5: =$Y$2*G5*Q5 -> 7.18 | AD5: =$Y$2*G5*Q5 -> 7.18 | AE5: =AD5+AC5+AB5 -> 258.33333 | AG5: =(R5-86.16)/6*I5 -> 243.97333 | AH5: =$Y$2*I5*Q5 -> 7.18 | AI5: =$Y$2*I5*Q5 -> 7.18 | AJ5: =AI5+AH5+AG5 -> 258.33333 | AL5: =(R5-86.16)/6*K5 -> 243.97333 | AM5: =$Y$2*K5*Q5 -> 7.18 | AN5: =$Y$2*K5*Q5 -> 7.18 | AO5: =AN5+AM5+AL5 -> 258.33333 | AQ5: =(R5-86.16)/6*M5 -> 243.97333 | AR5: =$Y$2*M5*Q5 -> 7.18 | AS5: =$Y$2*M5*Q5 -> 7.18 | AT5: =AS5+AR5+AQ5 -> 258.33333 | AV5: =(R5-86.16)/6*O5 -> 243.97333 | AW5: =$Y$2*O5*Q5 -> 7.18 | AX5: =$Y$2*O5*Q5 -> 7.18 | AY5: =AX5+AW5+AV5 -> 258.33333 | AZ5: =+AY5+AT5+AO5++AJ5+AE5+Z5 -> 1550 | BA5: =((AZ5-BB5-BC5-BD5-BE5-BF5)+BI5+BJ5+BK5+BL5+BM5+BN5+BO5) -> 2100 | BG5: BONO+ B ASIS | BI5: 300 | BJ5: 250 | BU5: 420
A6: 424 | B6: 6 | C6: =+C5+1 -> 3 | D6: Balderas Balderas Myriam Ivet | E6: 1 | G6: 1 | I6: 1 | K6: 1 | M6: 1 | O6: 1 | Q6: =IF((E6+G6+I6+K6+M6+O6)=6,1,0) -> 1 | R6: 3000 | S6: =+BH6 -> 0 | T6: =+BA6 -> 3000 | U6: =+BP6 -> 0 | V6: =+BG6 -> 0 | W6: =(R6-86.16)/6*E6 -> 485.64 | X6: =$Y$2*E6*Q6 -> 7.18 | Y6: =$Y$2*E6*Q6 -> 7.18 | Z6: =Y6+X6+W6 -> 500 | AB6: =(R6-86.16)/6*G6 -> 485.64 | AC6: =$Y$2*G6*Q6 -> 7.18 | AD6: =$Y$2*G6*Q6 -> 7.18 | AE6: =AD6+AC6+AB6 -> 500 | AG6: =(R6-86.16)/6*I6 -> 485.64 | AH6: =$Y$2*I6*Q6 -> 7.18 | AI6: =$Y$2*I6*Q6 -> 7.18 | AJ6: =AI6+AH6+AG6 -> 500 | AL6: =(R6-86.16)/6*K6 -> 485.64 | AM6: =$Y$2*K6*Q6 -> 7.18 | AN6: =$Y$2*K6*Q6 -> 7.18 | AO6: =AN6+AM6+AL6 -> 500 | AQ6: =(R6-86.16)/6*M6 -> 485.64 | AR6: =$Y$2*M6*Q6 -> 7.18 | AS6: =$Y$2*M6*Q6 -> 7.18 | AT6: =AS6+AR6+AQ6 -> 500 | AV6: =(R6-86.16)/6*O6 -> 485.64 | AW6: =$Y$2*O6*Q6 -> 7.18 | AX6: =$Y$2*O6*Q6 -> 7.18 | AY6: =AX6+AW6+AV6 -> 500 | AZ6: =+AY6+AT6+AO6++AJ6+AE6+Z6 -> 3000 | BA6: =((AZ6-BB6-BC6-BD6-BE6-BF6)+BI6+BJ6+BK6+BL6+BM6+BN6+BO6) -> 3000 | BU6: 424
B7: 149 | C7: =+C6+1 -> 4 | D7: Carrillo Alvarado Erika Miranda | E7: 1 | G7: 1 | I7: 1 | K7: 1 | M7: 1 | O7: 1 | Q7: =IF((E7+G7+I7+K7+M7+O7)=6,1,0) -> 1 | R7: =IF(Q7=1,1550,850) -> 1550 | S7: =+BH7 -> 0 | T7: =+BA7 -> 1800 | U7: =+BP7 -> 0 | V7: =+BG7 -> BONO+ B ASIS | W7: =(R7-86.16)/6*E7 -> 243.97333 | X7: =$Y$2*E7*Q7 -> 7.18 | Y7: =$Y$2*E7*Q7 -> 7.18 | Z7: =Y7+X7+W7 -> 258.33333 | AB7: =(R7-86.16)/6*G7 -> 243.97333 | AC7: =$Y$2*G7*Q7 -> 7.18 | AD7: =$Y$2*G7*Q7 -> 7.18 | AE7: =AD7+AC7+AB7 -> 258.33333 | AG7: =(R7-86.16)/6*I7 -> 243.97333 | AH7: =$Y$2*I7*Q7 -> 7.18 | AI7: =$Y$2*I7*Q7 -> 7.18 | AJ7: =AI7+AH7+AG7 -> 258.33333 | AL7: =(R7-86.16)/6*K7 -> 243.97333 | AM7: =$Y$2*K7*Q7 -> 7.18 | AN7: =$Y$2*K7*Q7 -> 7.18 | AO7: =AN7+AM7+AL7 -> 258.33333 | AQ7: =(R7-86.16)/6*M7 -> 243.97333 | AR7: =$Y$2*M7*Q7 -> 7.18 | AS7: =$Y$2*M7*Q7 -> 7.18 | AT7: =AS7+AR7+AQ7 -> 258.33333 | AV7: =(R7-86.16)/6*O7 -> 243.97333 | AW7: =$Y$2*O7*Q7 -> 7.18 | AX7: =$Y$2*O7*Q7 -> 7.18 | AY7: =AX7+AW7+AV7 -> 258.33333 | AZ7: =+AY7+AT7+AO7++AJ7+AE7+Z7 -> 1550 | BA7: =((AZ7-BB7-BC7-BD7-BE7-BF7)+BI7+BJ7+BK7+BL7+BM7+BN7+BO7) -> 1800 | BG7: BONO+ B ASIS | BI7: 100 | BJ7: 150
B8: 95 | C8: =+C7+1 -> 5 | D8: Carrillo Delgado Judith | E8: 1 | G8: 1 | I8: 1 | K8: 1 | M8: 1 | O8: 1 | Q8: =IF((E8+G8+I8+K8+M8+O8)=6,1,0) -> 1 | R8: =IF(Q8=1,1550,850) -> 1550 | S8: =+BH8 -> 0 | T8: =+BA8 -> 1950 | U8: =+BP8 -> 0 | V8: =+BG8 -> BONO+ B ASIS | W8: =(R8-86.16)/6*E8 -> 243.97333 | X8: =$Y$2*E8*Q8 -> 7.18 | Y8: =$Y$2*E8*Q8 -> 7.18 | Z8: =Y8+X8+W8 -> 258.33333 | AB8: =(R8-86.16)/6*G8 -> 243.97333 | AC8: =$Y$2*G8*Q8 -> 7.18 | AD8: =$Y$2*G8*Q8 -> 7.18 | AE8: =AD8+AC8+AB8 -> 258.33333 | AG8: =(R8-86.16)/6*I8 -> 243.97333 | AH8: =$Y$2*I8*Q8 -> 7.18 | AI8: =$Y$2*I8*Q8 -> 7.18 | AJ8: =AI8+AH8+AG8 -> 258.33333 | AL8: =(R8-86.16)/6*K8 -> 243.97333 | AM8: =$Y$2*K8*Q8 -> 7.18 | AN8: =$Y$2*K8*Q8 -> 7.18 | AO8: =AN8+AM8+AL8 -> 258.33333 | AQ8: =(R8-86.16)/6*M8 -> 243.97333 | AR8: =$Y$2*M8*Q8 -> 7.18 | AS8: =$Y$2*M8*Q8 -> 7.18 | AT8: =AS8+AR8+AQ8 -> 258.33333 | AV8: =(R8-86.16)/6*O8 -> 243.97333 | AW8: =$Y$2*O8*Q8 -> 7.18 | AX8: =$Y$2*O8*Q8 -> 7.18 | AY8: =AX8+AW8+AV8 -> 258.33333 | AZ8: =+AY8+AT8+AO8++AJ8+AE8+Z8 -> 1550 | BA8: =((AZ8-BB8-BC8-BD8-BE8-BF8)+BI8+BJ8+BK8+BL8+BM8+BN8+BO8) -> 1950 | BG8: BONO+ B ASIS | BI8: 250 | BJ8: 150
B9: 59 | C9: =+C8+1 -> 6 | D9: Castro Viaña Mario Ivan | E9: 1 | G9: 1 | I9: 1 | K9: 1 | M9: 1 | O9: 1 | Q9: =IF((E9+G9+I9+K9+M9+O9)=6,1,0) -> 1 | R9: =IF(Q9=1,1550,850) -> 1550 | S9: =+BH9 -> 0 | T9: =+BA9 -> 1950 | U9: =+BP9 -> 0 | V9: =+BG9 -> BONO+ B ASIS | W9: =(R9-86.16)/6*E9 -> 243.97333 | X9: =$Y$2*E9*Q9 -> 7.18 | Y9: =$Y$2*E9*Q9 -> 7.18 | Z9: =Y9+X9+W9 -> 258.33333 | AB9: =(R9-86.16)/6*G9 -> 243.97333 | AC9: =$Y$2*G9*Q9 -> 7.18 | AD9: =$Y$2*G9*Q9 -> 7.18 | AE9: =AD9+AC9+AB9 -> 258.33333 | AG9: =(R9-86.16)/6*I9 -> 243.97333 | AH9: =$Y$2*I9*Q9 -> 7.18 | AI9: =$Y$2*I9*Q9 -> 7.18 | AJ9: =AI9+AH9+AG9 -> 258.33333 | AL9: =(R9-86.16)/6*K9 -> 243.97333 | AM9: =$Y$2*K9*Q9 -> 7.18 | AN9: =$Y$2*K9*Q9 -> 7.18 | AO9: =AN9+AM9+AL9 -> 258.33333 | AQ9: =(R9-86.16)/6*M9 -> 243.97333 | AR9: =$Y$2*M9*Q9 -> 7.18 | AS9: =$Y$2*M9*Q9 -> 7.18 | AT9: =AS9+AR9+AQ9 -> 258.33333 | AV9: =(R9-86.16)/6*O9 -> 243.97333 | AW9: =$Y$2*O9*Q9 -> 7.18 | AX9: =$Y$2*O9*Q9 -> 7.18 | AY9: =AX9+AW9+AV9 -> 258.33333 | AZ9: =+AY9+AT9+AO9++AJ9+AE9+Z9 -> 1550 | BA9: =((AZ9-BB9-BC9-BD9-BE9-BF9)+BI9+BJ9+BK9+BL9+BM9+BN9+BO9) -> 1950 | BG9: BONO+ B ASIS | BI9: 250 | BJ9: 150
B10: 73 | C10: =+C9+1 -> 7 | D10: Garcia Ortega Leslie Coraima | E10: 1 | G10: 1 | I10: 1 | K10: 1 | M10: 1 | O10: 1 | Q10: =IF((E10+G10+I10+K10+M10+O10)=6,1,0) -> 1 | R10: =IF(Q10=1,1550,850) -> 1550 | S10: =+BH10 -> 0 | T10: =+BA10 -> 1950 | U10: =+BP10 -> 0 | V10: =+BG10 -> BONO+ B ASIS | W10: =(R10-86.16)/6*E10 -> 243.97333 | X10: =$Y$2*E10*Q10 -> 7.18 | Y10: =$Y$2*E10*Q10 -> 7.18 | Z10: =Y10+X10+W10 -> 258.33333 | AB10: =(R10-86.16)/6*G10 -> 243.97333 | AC10: =$Y$2*G10*Q10 -> 7.18 | AD10: =$Y$2*G10*Q10 -> 7.18 | AE10: =AD10+AC10+AB10 -> 258.33333 | AG10: =(R10-86.16)/6*I10 -> 243.97333 | AH10: =$Y$2*I10*Q10 -> 7.18 | AI10: =$Y$2*I10*Q10 -> 7.18 | AJ10: =AI10+AH10+AG10 -> 258.33333 | AL10: =(R10-86.16)/6*K10 -> 243.97333 | AM10: =$Y$2*K10*Q10 -> 7.18 | AN10: =$Y$2*K10*Q10 -> 7.18 | AO10: =AN10+AM10+AL10 -> 258.33333 | AQ10: =(R10-86.16)/6*M10 -> 243.97333 | AR10: =$Y$2*M10*Q10 -> 7.18 | AS10: =$Y$2*M10*Q10 -> 7.18 | AT10: =AS10+AR10+AQ10 -> 258.33333 | AV10: =(R10-86.16)/6*O10 -> 243.97333 | AW10: =$Y$2*O10*Q10 -> 7.18 | AX10: =$Y$2*O10*Q10 -> 7.18 | AY10: =AX10+AW10+AV10 -> 258.33333 | AZ10: =+AY10+AT10+AO10++AJ10+AE10+Z10 -> 1550 | BA10: =((AZ10-BB10-BC10-BD10-BE10-BF10)+BI10+BJ10+BK10+BL10+BM10+BN10+BO10) -> 1950 | BG10: BONO+ B ASIS | BI10: 250 | BJ10: 150
A11: 424 | B11: 26 | C11: =+C10+1 -> 8 | D11: Medrano Suarez Jose Adolfo | E11: 1 | G11: 1 | I11: 1 | K11: 1 | M11: 1 | O11: 1 | Q11: =IF((E11+G11+I11+K11+M11+O11)=6,1,0) -> 1 | R11: 2500 | S11: =+BH11 -> 0 | T11: =+BA11 -> 2500 | U11: =+BP11 -> 0 | V11: =+BG11 -> 0 | W11: =(R11-86.16)/6*E11 -> 402.30667 | X11: =$Y$2*E11*Q11 -> 7.18 | Y11: =$Y$2*E11*Q11 -> 7.18 | Z11: =Y11+X11+W11 -> 416.66667 | AB11: =(R11-86.16)/6*G11 -> 402.30667 | AC11: =$Y$2*G11*Q11 -> 7.18 | AD11: =$Y$2*G11*Q11 -> 7.18 | AE11: =AD11+AC11+AB11 -> 416.66667 | AG11: =(R11-86.16)/6*I11 -> 402.30667 | AH11: =$Y$2*I11*Q11 -> 7.18 | AI11: =$Y$2*I11*Q11 -> 7.18 | AJ11: =AI11+AH11+AG11 -> 416.66667 | AL11: =(R11-86.16)/6*K11 -> 402.30667 | AM11: =$Y$2*K11*Q11 -> 7.18 | AN11: =$Y$2*K11*Q11 -> 7.18 | AO11: =AN11+AM11+AL11 -> 416.66667 | AQ11: =(R11-86.16)/6*M11 -> 402.30667 | AR11: =$Y$2*M11*Q11 -> 7.18 | AS11: =$Y$2*M11*Q11 -> 7.18 | AT11: =AS11+AR11+AQ11 -> 416.66667 | AV11: =(R11-86.16)/6*O11 -> 402.30667 | AW11: =$Y$2*O11*Q11 -> 7.18 | AX11: =$Y$2*O11*Q11 -> 7.18 | AY11: =AX11+AW11+AV11 -> 416.66667 | AZ11: =+AY11+AT11+AO11++AJ11+AE11+Z11 -> 2500 | BA11: =((AZ11-BB11-BC11-BD11-BE11-BF11)+BI11+BJ11+BK11+BL11+BM11+BN11+BO11) -> 2500 | BU11: 424
B12: 169 | C12: =+C11+1 -> 9 | D12: Ramirez Requejo Maria Guadalupe | E12: 1 | G12: 1 | I12: 1 | K12: 1 | M12: 1 | O12: 1 | Q12: =IF((E12+G12+I12+K12+M12+O12)=6,1,0) -> 1 | R12: =IF(Q12=1,1550,850) -> 1550 | S12: =+BH12 -> 0 | T12: =+BA12 -> 1700 | U12: =+BP12 -> 0 | V12: =+BG12 -> BONO | W12: =(R12-86.16)/6*E12 -> 243.97333 | X12: =$Y$2*E12*Q12 -> 7.18 | Y12: =$Y$2*E12*Q12 -> 7.18 | Z12: =Y12+X12+W12 -> 258.33333 | AB12: =(R12-86.16)/6*G12 -> 243.97333 | AC12: =$Y$2*G12*Q12 -> 7.18 | AD12: =$Y$2*G12*Q12 -> 7.18 | AE12: =AD12+AC12+AB12 -> 258.33333 | AG12: =(R12-86.16)/6*I12 -> 243.97333 | AH12: =$Y$2*I12*Q12 -> 7.18 | AI12: =$Y$2*I12*Q12 -> 7.18 | AJ12: =AI12+AH12+AG12 -> 258.33333 | AL12: =(R12-86.16)/6*K12 -> 243.97333 | AM12: =$Y$2*K12*Q12 -> 7.18 | AN12: =$Y$2*K12*Q12 -> 7.18 | AO12: =AN12+AM12+AL12 -> 258.33333 | AQ12: =(R12-86.16)/6*M12 -> 243.97333 | AR12: =$Y$2*M12*Q12 -> 7.18 | AS12: =$Y$2*M12*Q12 -> 7.18 | AT12: =AS12+AR12+AQ12 -> 258.33333 | AV12: =(R12-86.16)/6*O12 -> 243.97333 | AW12: =$Y$2*O12*Q12 -> 7.18 | AX12: =$Y$2*O12*Q12 -> 7.18 | AY12: =AX12+AW12+AV12 -> 258.33333 | AZ12: =+AY12+AT12+AO12++AJ12+AE12+Z12 -> 1550 | BA12: =((AZ12-BB12-BC12-BD12-BE12-BF12)+BI12+BJ12+BK12+BL12+BM12+BN12+BO12) -> 1700 | BG12: BONO | BJ12: 150
B13: 152 | C13: =+C12+1 -> 10 | D13: Ruiz Valenzuela Cynthia Marissa | E13: 1 | G13: 1 | I13: 1 | K13: 1 | M13: 1 | O13: 1 | Q13: =IF((E13+G13+I13+K13+M13+O13)=6,1,0) -> 1 | R13: =IF(Q13=1,1550,850) -> 1550 | S13: =+BH13 -> 0 | T13: =+BA13 -> 2000 | U13: =+BP13 -> 0 | V13: =+BG13 -> BONO+B ASIS | W13: =(R13-86.16)/6*E13 -> 243.97333 | X13: =$Y$2*E13*Q13 -> 7.18 | Y13: =$Y$2*E13*Q13 -> 7.18 | Z13: =Y13+X13+W13 -> 258.33333 | AB13: =(R13-86.16)/6*G13 -> 243.97333 | AC13: =$Y$2*G13*Q13 -> 7.18 | AD13: =$Y$2*G13*Q13 -> 7.18 | AE13: =AD13+AC13+AB13 -> 258.33333 | AG13: =(R13-86.16)/6*I13 -> 243.97333 | AH13: =$Y$2*I13*Q13 -> 7.18 | AI13: =$Y$2*I13*Q13 -> 7.18 | AJ13: =AI13+AH13+AG13 -> 258.33333 | AL13: =(R13-86.16)/6*K13 -> 243.97333 | AM13: =$Y$2*K13*Q13 -> 7.18 | AN13: =$Y$2*K13*Q13 -> 7.18 | AO13: =AN13+AM13+AL13 -> 258.33333 | AQ13: =(R13-86.16)/6*M13 -> 243.97333 | AR13: =$Y$2*M13*Q13 -> 7.18 | AS13: =$Y$2*M13*Q13 -> 7.18 | AT13: =AS13+AR13+AQ13 -> 258.33333 | AV13: =(R13-86.16)/6*O13 -> 243.97333 | AW13: =$Y$2*O13*Q13 -> 7.18 | AX13: =$Y$2*O13*Q13 -> 7.18 | AY13: =AX13+AW13+AV13 -> 258.33333 | AZ13: =+AY13+AT13+AO13++AJ13+AE13+Z13 -> 1550 | BA13: =((AZ13-BB13-BC13-BD13-BE13-BF13)+BI13+BJ13+BK13+BL13+BM13+BN13+BO13) -> 2000 | BG13: BONO+B ASIS | BI13: 300 | BJ13: 150
B14: 146 | C14: =+C13+1 -> 11 | D14: Salazar Martinez Yohana Cecilia | E14: 1 | G14: 1 | I14: 1 | K14: 1 | M14: 1 | O14: 1 | Q14: =IF((E14+G14+I14+K14+M14+O14)=6,1,0) -> 1 | R14: =IF(Q14=1,1550,850) -> 1550 | S14: =+BH14 -> 0 | T14: =+BA14 -> 1950 | U14: =+BP14 -> 0 | V14: =+BG14 -> BONO+B ASIS | W14: =(R14-86.16)/6*E14 -> 243.97333 | X14: =$Y$2*E14*Q14 -> 7.18 | Y14: =$Y$2*E14*Q14 -> 7.18 | Z14: =Y14+X14+W14 -> 258.33333 | AB14: =(R14-86.16)/6*G14 -> 243.97333 | AC14: =$Y$2*G14*Q14 -> 7.18 | AD14: =$Y$2*G14*Q14 -> 7.18 | AE14: =AD14+AC14+AB14 -> 258.33333 | AG14: =(R14-86.16)/6*I14 -> 243.97333 | AH14: =$Y$2*I14*Q14 -> 7.18 | AI14: =$Y$2*I14*Q14 -> 7.18 | AJ14: =AI14+AH14+AG14 -> 258.33333 | AL14: =(R14-86.16)/6*K14 -> 243.97333 | AM14: =$Y$2*K14*Q14 -> 7.18 | AN14: =$Y$2*K14*Q14 -> 7.18 | AO14: =AN14+AM14+AL14 -> 258.33333 | AQ14: =(R14-86.16)/6*M14 -> 243.97333 | AR14: =$Y$2*M14*Q14 -> 7.18 | AS14: =$Y$2*M14*Q14 -> 7.18 | AT14: =AS14+AR14+AQ14 -> 258.33333 | AV14: =(R14-86.16)/6*O14 -> 243.97333 | AW14: =$Y$2*O14*Q14 -> 7.18 | AX14: =$Y$2*O14*Q14 -> 7.18 | AY14: =AX14+AW14+AV14 -> 258.33333 | AZ14: =+AY14+AT14+AO14++AJ14+AE14+Z14 -> 1550 | BA14: =((AZ14-BB14-BC14-BD14-BE14-BF14)+BI14+BJ14+BK14+BL14+BM14+BN14+BO14) -> 1950 | BG14: BONO+B ASIS | BI14: 250 | BJ14: 150
A15: 470 | B15: 51 | C15: =+C14+1 -> 12 | D15: Valenzuela Rosales Jose Miguel | E15: 1 | G15: 1 | I15: 1 | K15: 1 | M15: 1 | O15: 1 | Q15: =IF((E15+G15+I15+K15+M15+O15)=6,1,0) -> 1 | R15: 3000 | S15: =+BH15 -> 0 | T15: =+BA15 -> 5585.71 | U15: =+BP15 -> 0 | V15: =+BG15 -> BONO+FINIQUITO | W15: =(R15-86.16)/6*E15 -> 485.64 | X15: =$Y$2*E15*Q15 -> 7.18 | Y15: =$Y$2*E15*Q15 -> 7.18 | Z15: =Y15+X15+W15 -> 500 | AB15: =(R15-86.16)/6*G15 -> 485.64 | AC15: =$Y$2*G15*Q15 -> 7.18 | AD15: =$Y$2*G15*Q15 -> 7.18 | AE15: =AD15+AC15+AB15 -> 500 | AG15: =(R15-86.16)/6*I15 -> 485.64 | AH15: =$Y$2*I15*Q15 -> 7.18 | AI15: =$Y$2*I15*Q15 -> 7.18 | AJ15: =AI15+AH15+AG15 -> 500 | AL15: =(R15-86.16)/6*K15 -> 485.64 | AM15: =$Y$2*K15*Q15 -> 7.18 | AN15: =$Y$2*K15*Q15 -> 7.18 | AO15: =AN15+AM15+AL15 -> 500 | AQ15: =(R15-86.16)/6*M15 -> 485.64 | AR15: =$Y$2*M15*Q15 -> 7.18 | AS15: =$Y$2*M15*Q15 -> 7.18 | AT15: =AS15+AR15+AQ15 -> 500 | AV15: =(R15-86.16)/6*O15 -> 485.64 | AW15: =$Y$2*O15*Q15 -> 7.18 | AX15: =$Y$2*O15*Q15 -> 7.18 | AY15: =AX15+AW15+AV15 -> 500 | AZ15: =+AY15+AT15+AO15++AJ15+AE15+Z15 -> 3000 | BA15: =((AZ15-BB15-BC15-BD15-BE15-BF15)+BI15+BJ15+BK15+BL15+BM15+BN15+BO15) -> 5585.71 | BG15: BONO+FINIQUITO | BI15: 1000 | BL15: 1585.71 | BU15: 470
A16: 429 | E16: =SUM(E4:E15) -> 12 | G16: =SUM(G4:G15) -> 12 | I16: =SUM(I4:I15) -> 12 | K16: =SUM(K4:K15) -> 12 | M16: =SUM(M4:M15) -> 12 | O16: =SUM(O4:O15) -> 12 | BU16: 429
A17: 430 | BU17: 430
A18: 431 | B18: REAL | C18: PR | G18: L | I18: M | K18: M | M18: J | O18: V | Q18: S | BU18: 431
A19: 432 | B19: =E16 -> 12 | C19: =G25 -> 12 | D19: =+B19-C19 -> 0 | R19: PROM | BU19: 432
A20: 433 | B20: =G16 -> 12 | C20: =I25 -> 12 | D20: =+B20-C20 -> 0 | E20: LIDER | G20: 1 | I20: 1 | K20: 1 | M20: 1 | O20: 1 | Q20: 1 | R20: =AVERAGE(G20,I20,K20,M20,O20,Q20) -> 1 | BU20: 433
A21: 434 | B21: =I16 -> 12 | C21: =K25 -> 12 | D21: =+B21-C21 -> 0 | E21: CALIDAD | G21: 1 | I21: 1 | K21: 1 | M21: 1 | O21: 1 | Q21: 1 | R21: =AVERAGE(G21,I21,K21,M21,O21,Q21) -> 1 | BU21: 434
A22: 435 | B22: =K16 -> 12 | C22: =M25 -> 12 | D22: =+B22-C22 -> 0 | E22: MECANICO | G22: 2 | I22: 2 | K22: 2 | M22: 2 | O22: 2 | Q22: 2 | R22: =AVERAGE(G22,I22,K22,M22,O22,Q22) -> 2 | BU22: 435
A23: 436 | B23: =M16 -> 12 | C23: =O25 -> 12 | D23: =+B23-C23 -> 0 | E23: MANUAL | G23: 8 | I23: 8 | K23: 8 | M23: 8 | O23: 8 | Q23: 8 | R23: =AVERAGE(G23,I23,K23,M23,O23,Q23) -> 8 | BU23: 436
A24: 437 | B24: =O16 -> 12 | C24: =Q25 -> 12 | D24: =+B24-C24 -> 0 | E24: MTTO | G24: 0 | I24: 0 | K24: 0 | M24: 0 | O24: 0 | Q24: 0 | R24: =AVERAGE(G24,I24,K24,M24,O24,Q24) -> 0 | BU24: 437
A25: 438 | G25: =SUM(G20:G24) -> 12 | I25: =SUM(I20:I24) -> 12 | K25: =SUM(K20:K24) -> 12 | M25: =SUM(M20:M24) -> 12 | O25: =SUM(O20:O24) -> 12 | Q25: =SUM(Q20:Q24) -> 12 | R25: =AVERAGE(G25,I25,K25,M25,O25,Q25) -> 12 | BU25: 438
A26: 439 | BU26: 439
A27: 440 | BU27: 440
A28: 441 | BU28: 441
A29: 442 | B29: TEJIDO 2 | D29: 3ER TURNO | R29: =$V2 -> DEL 08 AL 14 ENERO 24 | BU29: 442
A30: 443 | E30: L | G30: M | I30: M | K30: J | M30: V | O30: S | V30: 3 | BU30: 443
A31: 444 | B31: 9 | C31: =+C30+1 -> 1 | D31: Bustamante Villegas Osvaldo | E31: 1 | G31: 1 | I31: 1 | K31: 1 | M31: 1 | O31: 1 | Q31: =IF((E31+G31+I31+K31+M31+O31)=6,1,0) -> 1 | R31: 3000 | S31: =+BH31 -> 0 | T31: =+BA31 -> 3000 | U31: =+BP31 -> 0 | V31: =+BG31 -> 0 | W31: =(R31-86.16)/6*E31 -> 485.64 | X31: =$Y$2*E31*Q31 -> 7.18 | Y31: =$Y$2*E31*Q31 -> 7.18 | Z31: =Y31+X31+W31 -> 500 | AB31: =(R31-86.16)/6*G31 -> 485.64 | AC31: =$Y$2*G31*Q31 -> 7.18 | AD31: =$Y$2*G31*Q31 -> 7.18 | AE31: =AD31+AC31+AB31 -> 500 | AG31: =(R31-86.16)/6*I31 -> 485.64 | AH31: =$Y$2*I31*Q31 -> 7.18 | AI31: =$Y$2*I31*Q31 -> 7.18 | AJ31: =AI31+AH31+AG31 -> 500 | AL31: =(R31-86.16)/6*K31 -> 485.64 | AM31: =$Y$2*K31*Q31 -> 7.18 | AN31: =$Y$2*K31*Q31 -> 7.18 | AO31: =AN31+AM31+AL31 -> 500 | AQ31: =(R31-86.16)/6*M31 -> 485.64 | AR31: =$Y$2*M31*Q31 -> 7.18 | AS31: =$Y$2*M31*Q31 -> 7.18 | AT31: =AS31+AR31+AQ31 -> 500 | AV31: =(R31-86.16)/6*O31 -> 485.64 | AW31: =$Y$2*O31*Q31 -> 7.18 | AX31: =$Y$2*O31*Q31 -> 7.18 | AY31: =AX31+AW31+AV31 -> 500 | AZ31: =+AY31+AT31+AO31++AJ31+AE31+Z31 -> 3000 | BA31: =((AZ31-BB31-BC31-BD31-BE31-BF31)+BI31+BJ31+BK31+BL31+BM31+BN31+BO31) -> 3000 | BU31: 444
A32: 445 | B32: 12 | C32: =+C31+1 -> 2 | D32: Diaz Martinez Angela Elizabeth | E32: 1 | G32: 1 | I32: 1 | K32: 1 | M32: 1 | O32: 1 | Q32: =IF((E32+G32+I32+K32+M32+O32)=6,1,0) -> 1 | R32: =IF(Q32=1,1550,850) -> 1550 | S32: =+BH32 -> 0 | T32: =+BA32 -> 2100 | U32: =+BP32 -> 0 | V32: =+BG32 -> BONO+B ASIS | W32: =(R32-86.16)/6*E32 -> 243.97333 | X32: =$Y$2*E32*Q32 -> 7.18 | Y32: =$Y$2*E32*Q32 -> 7.18 | Z32: =Y32+X32+W32 -> 258.33333 | AB32: =(R32-86.16)/6*G32 -> 243.97333 | AC32: =$Y$2*G32*Q32 -> 7.18 | AD32: =$Y$2*G32*Q32 -> 7.18 | AE32: =AD32+AC32+AB32 -> 258.33333 | AG32: =(R32-86.16)/6*I32 -> 243.97333 | AH32: =$Y$2*I32*Q32 -> 7.18 | AI32: =$Y$2*I32*Q32 -> 7.18 | AJ32: =AI32+AH32+AG32 -> 258.33333 | AL32: =(R32-86.16)/6*K32 -> 243.97333 | AM32: =$Y$2*K32*Q32 -> 7.18 | AN32: =$Y$2*K32*Q32 -> 7.18 | AO32: =AN32+AM32+AL32 -> 258.33333 | AQ32: =(R32-86.16)/6*M32 -> 243.97333 | AR32: =$Y$2*M32*Q32 -> 7.18 | AS32: =$Y$2*M32*Q32 -> 7.18 | AT32: =AS32+AR32+AQ32 -> 258.33333 | AV32: =(R32-86.16)/6*O32 -> 243.97333 | AW32: =$Y$2*O32*Q32 -> 7.18 | AX32: =$Y$2*O32*Q32 -> 7.18 | AY32: =AX32+AW32+AV32 -> 258.33333 | AZ32: =+AY32+AT32+AO32++AJ32+AE32+Z32 -> 1550 | BA32: =((AZ32-BB32-BC32-BD32-BE32-BF32)+BI32+BJ32+BK32+BL32+BM32+BN32+BO32) -> 2100 | BG32: BONO+B ASIS | BI32: 300 | BJ32: 250 | BU32: 445
B33: 168 | C33: =+C32+1 -> 3 | D33: Espinoza Ponce Juan Jose | E33: 1 | G33: 1 | I33: 1 | K33: 1 | M33: 1 | O33: 1 | Q33: =IF((E33+G33+I33+K33+M33+O33)=6,1,0) -> 1 | R33: =IF(Q33=1,1550,850) -> 1550 | S33: =+BH33 -> 0 | T33: =+BA33 -> 1800 | U33: =+BP33 -> 0 | V33: =+BG33 -> B ASIS | W33: =(R33-86.16)/6*E33 -> 243.97333 | X33: =$Y$2*E33*Q33 -> 7.18 | Y33: =$Y$2*E33*Q33 -> 7.18 | Z33: =Y33+X33+W33 -> 258.33333 | AB33: =(R33-86.16)/6*G33 -> 243.97333 | AC33: =$Y$2*G33*Q33 -> 7.18 | AD33: =$Y$2*G33*Q33 -> 7.18 | AE33: =AD33+AC33+AB33 -> 258.33333 | AG33: =(R33-86.16)/6*I33 -> 243.97333 | AH33: =$Y$2*I33*Q33 -> 7.18 | AI33: =$Y$2*I33*Q33 -> 7.18 | AJ33: =AI33+AH33+AG33 -> 258.33333 | AL33: =(R33-86.16)/6*K33 -> 243.97333 | AM33: =$Y$2*K33*Q33 -> 7.18 | AN33: =$Y$2*K33*Q33 -> 7.18 | AO33: =AN33+AM33+AL33 -> 258.33333 | AQ33: =(R33-86.16)/6*M33 -> 243.97333 | AR33: =$Y$2*M33*Q33 -> 7.18 | AS33: =$Y$2*M33*Q33 -> 7.18 | AT33: =AS33+AR33+AQ33 -> 258.33333 | AV33: =(R33-86.16)/6*O33 -> 243.97333 | AW33: =$Y$2*O33*Q33 -> 7.18 | AX33: =$Y$2*O33*Q33 -> 7.18 | AY33: =AX33+AW33+AV33 -> 258.33333 | AZ33: =+AY33+AT33+AO33++AJ33+AE33+Z33 -> 1550 | BA33: =((AZ33-BB33-BC33-BD33-BE33-BF33)+BI33+BJ33+BK33+BL33+BM33+BN33+BO33) -> 1800 | BG33: B ASIS | BI33: 100 | BJ33: 150
A34: 445 | B34: 16 | C34: =+C33+1 -> 4 | D34: Favela Saucedo Idalia Azucena | E34: 0 | F34: INC | G34: 0 | H34: INC | I34: 0 | J34: INC | K34: 0 | L34: INC | M34: 0 | N34: INC | O34: 0 | P34: INC | Q34: =IF((E34+G34+I34+K34+M34+O34)=6,1,0) -> 0 | R34: =IF(Q34=1,1550,850) -> 850 | S34: =+BH34 -> 0 | T34: =+BA34 -> 0 | U34: =+BP34 -> 0 | V34: =+BG34 -> 0 | W34: =(R34-86.16)/6*E34 -> 0 | X34: =$Y$2*E34*Q34 -> 0 | Y34: =$Y$2*E34*Q34 -> 0 | Z34: =Y34+X34+W34 -> 0 | AB34: =(R34-86.16)/6*G34 -> 0 | AC34: =$Y$2*G34*Q34 -> 0 | AD34: =$Y$2*G34*Q34 -> 0 | AE34: =AD34+AC34+AB34 -> 0 | AG34: =(R34-86.16)/6*I34 -> 0 | AH34: =$Y$2*I34*Q34 -> 0 | AI34: =$Y$2*I34*Q34 -> 0 | AJ34: =AI34+AH34+AG34 -> 0 | AL34: =(R34-86.16)/6*K34 -> 0 | AM34: =$Y$2*K34*Q34 -> 0 | AN34: =$Y$2*K34*Q34 -> 0 | AO34: =AN34+AM34+AL34 -> 0 | AQ34: =(R34-86.16)/6*M34 -> 0 | AR34: =$Y$2*M34*Q34 -> 0 | AS34: =$Y$2*M34*Q34 -> 0 | AT34: =AS34+AR34+AQ34 -> 0 | AV34: =(R34-86.16)/6*O34 -> 0 | AW34: =$Y$2*O34*Q34 -> 0 | AX34: =$Y$2*O34*Q34 -> 0 | AY34: =AX34+AW34+AV34 -> 0 | AZ34: =+AY34+AT34+AO34++AJ34+AE34+Z34 -> 0 | BA34: =((AZ34-BB34-BC34-BD34-BE34-BF34)+BI34+BJ34+BK34+BL34+BM34+BN34+BO34) -> 0 | BU34: 445
B35: 171 | C35: =+C34+1 -> 5 | D35: Juarez Sifuentes Sandra | E35: 1 | G35: 1 | I35: 1 | K35: 1 | M35: 1 | O35: 0 | P35: F | Q35: =IF((E35+G35+I35+K35+M35+O35)=6,1,0) -> 0 | R35: =IF(Q35=1,1550,850) -> 850 | S35: =+BH35 -> 0 | T35: =+BA35 -> 966.66333 | U35: =+BP35 -> 0 | V35: =+BG35 -> 0 | W35: =(R35-86.16)/6*E35 -> 127.30667 | X35: =$Y$2*E35*Q35 -> 0 | Y35: =$Y$2*E35*Q35 -> 0 | Z35: =Y35+X35+W35 -> 127.30667 | AB35: =(R35-86.16)/6*G35 -> 127.30667 | AC35: =$Y$2*G35*Q35 -> 0 | AD35: =$Y$2*G35*Q35 -> 0 | AE35: =AD35+AC35+AB35 -> 127.30667 | AG35: =(R35-86.16)/6*I35 -> 127.30667 | AH35: =$Y$2*I35*Q35 -> 0 | AI35: =$Y$2*I35*Q35 -> 0 | AJ35: =AI35+AH35+AG35 -> 127.30667 | AL35: =(R35-86.16)/6*K35 -> 127.30667 | AM35: =$Y$2*K35*Q35 -> 0 | AN35: =$Y$2*K35*Q35 -> 0 | AO35: =AN35+AM35+AL35 -> 127.30667 | AQ35: =(R35-86.16)/6*M35 -> 127.30667 | AR35: =$Y$2*M35*Q35 -> 0 | AS35: =$Y$2*M35*Q35 -> 0 | AT35: =AS35+AR35+AQ35 -> 127.30667 | AV35: =(R35-86.16)/6*O35 -> 0 | AW35: =$Y$2*O35*Q35 -> 0 | AX35: =$Y$2*O35*Q35 -> 0 | AY35: =AX35+AW35+AV35 -> 0 | AZ35: =+AY35+AT35+AO35++AJ35+AE35+Z35 -> 636.53333 | BA35: =((AZ35-BB35-BC35-BD35-BE35-BF35)+BI35+BJ35+BK35+BL35+BM35+BN35+BO35) -> 966.66333 | BL35: 330.13
B36: 92 | C36: =+C35+1 -> 6 | D36: Martinez Sifuentes Mariana | E36: 1 | G36: 1 | I36: 1 | K36: 1 | M36: 1 | O36: 1 | Q36: =IF((E36+G36+I36+K36+M36+O36)=6,1,0) -> 1 | R36: =IF(Q36=1,1550,850) -> 1550 | S36: =+BH36 -> 0 | T36: =+BA36 -> 1800 | U36: =+BP36 -> 0 | V36: =+BG36 -> B ASIS | W36: =(R36-86.16)/6*E36 -> 243.97333 | X36: =$Y$2*E36*Q36 -> 7.18 | Y36: =$Y$2*E36*Q36 -> 7.18 | Z36: =Y36+X36+W36 -> 258.33333 | AB36: =(R36-86.16)/6*G36 -> 243.97333 | AC36: =$Y$2*G36*Q36 -> 7.18 | AD36: =$Y$2*G36*Q36 -> 7.18 | AE36: =AD36+AC36+AB36 -> 258.33333 | AG36: =(R36-86.16)/6*I36 -> 243.97333 | AH36: =$Y$2*I36*Q36 -> 7.18 | AI36: =$Y$2*I36*Q36 -> 7.18 | AJ36: =AI36+AH36+AG36 -> 258.33333 | AL36: =(R36-86.16)/6*K36 -> 243.97333 | AM36: =$Y$2*K36*Q36 -> 7.18 | AN36: =$Y$2*K36*Q36 -> 7.18 | AO36: =AN36+AM36+AL36 -> 258.33333 | AQ36: =(R36-86.16)/6*M36 -> 243.97333 | AR36: =$Y$2*M36*Q36 -> 7.18 | AS36: =$Y$2*M36*Q36 -> 7.18 | AT36: =AS36+AR36+AQ36 -> 258.33333 | AV36: =(R36-86.16)/6*O36 -> 243.97333 | AW36: =$Y$2*O36*Q36 -> 7.18 | AX36: =$Y$2*O36*Q36 -> 7.18 | AY36: =AX36+AW36+AV36 -> 258.33333 | AZ36: =+AY36+AT36+AO36++AJ36+AE36+Z36 -> 1550 | BA36: =((AZ36-BB36-BC36-BD36-BE36-BF36)+BI36+BJ36+BK36+BL36+BM36+BN36+BO36) -> 1800 | BG36: B ASIS | BI36: 100 | BJ36: 150
B37: 91 | C37: =+C36+1 -> 7 | D37: Medellin Rodriguez Yesenia Abigail | E37: 1 | G37: 1 | I37: 1 | K37: 1 | M37: 1 | O37: 1 | Q37: =IF((E37+G37+I37+K37+M37+O37)=6,1,0) -> 1 | R37: =IF(Q37=1,1550,850) -> 1550 | S37: =+BH37 -> 0 | T37: =+BA37 -> 1950 | U37: =+BP37 -> 0 | V37: =+BG37 -> BONO+B ASIS | W37: =(R37-86.16)/6*E37 -> 243.97333 | X37: =$Y$2*E37*Q37 -> 7.18 | Y37: =$Y$2*E37*Q37 -> 7.18 | Z37: =Y37+X37+W37 -> 258.33333 | AB37: =(R37-86.16)/6*G37 -> 243.97333 | AC37: =$Y$2*G37*Q37 -> 7.18 | AD37: =$Y$2*G37*Q37 -> 7.18 | AE37: =AD37+AC37+AB37 -> 258.33333 | AG37: =(R37-86.16)/6*I37 -> 243.97333 | AH37: =$Y$2*I37*Q37 -> 7.18 | AI37: =$Y$2*I37*Q37 -> 7.18 | AJ37: =AI37+AH37+AG37 -> 258.33333 | AL37: =(R37-86.16)/6*K37 -> 243.97333 | AM37: =$Y$2*K37*Q37 -> 7.18 | AN37: =$Y$2*K37*Q37 -> 7.18 | AO37: =AN37+AM37+AL37 -> 258.33333 | AQ37: =(R37-86.16)/6*M37 -> 243.97333 | AR37: =$Y$2*M37*Q37 -> 7.18 | AS37: =$Y$2*M37*Q37 -> 7.18 | AT37: =AS37+AR37+AQ37 -> 258.33333 | AV37: =(R37-86.16)/6*O37 -> 243.97333 | AW37: =$Y$2*O37*Q37 -> 7.18 | AX37: =$Y$2*O37*Q37 -> 7.18 | AY37: =AX37+AW37+AV37 -> 258.33333 | AZ37: =+AY37+AT37+AO37++AJ37+AE37+Z37 -> 1550 | BA37: =((AZ37-BB37-BC37-BD37-BE37-BF37)+BI37+BJ37+BK37+BL37+BM37+BN37+BO37) -> 1950 | BG37: BONO+B ASIS | BI37: 250 | BJ37: 150
A38: 448 | B38: 27 | C38: =+C37+1 -> 8 | D38: Minor Flores Adilene | E38: 1 | G38: 1 | I38: 1 | K38: 0 | L38: PSG | M38: 1 | O38: 1 | Q38: =IF((E38+G38+I38+K38+M38+O38)=6,1,0) -> 0 | R38: =IF(Q38=1,1550,850) -> 850 | S38: =+BH38 -> 0 | T38: =+BA38 -> 1508.3333 | U38: =+BP38 -> 0 | V38: =+BG38 -> BONO | W38: =(R38-86.16)/6*E38 -> 127.30667 | X38: =$Y$2*E38*Q38 -> 0 | Y38: =$Y$2*E38*Q38 -> 0 | Z38: =Y38+X38+W38 -> 127.30667 | AB38: =(R38-86.16)/6*G38 -> 127.30667 | AC38: =$Y$2*G38*Q38 -> 0 | AD38: =$Y$2*G38*Q38 -> 0 | AE38: =AD38+AC38+AB38 -> 127.30667 | AG38: =(R38-86.16)/6*I38 -> 127.30667 | AH38: =$Y$2*I38*Q38 -> 0 | AI38: =$Y$2*I38*Q38 -> 0 | AJ38: =AI38+AH38+AG38 -> 127.30667 | AL38: =(R38-86.16)/6*K38 -> 0 | AM38: =$Y$2*K38*Q38 -> 0 | AN38: =$Y$2*K38*Q38 -> 0 | AO38: =AN38+AM38+AL38 -> 0 | AQ38: =(R38-86.16)/6*M38 -> 127.30667 | AR38: =$Y$2*M38*Q38 -> 0 | AS38: =$Y$2*M38*Q38 -> 0 | AT38: =AS38+AR38+AQ38 -> 127.30667 | AV38: =(R38-86.16)/6*O38 -> 127.30667 | AW38: =$Y$2*O38*Q38 -> 0 | AX38: =$Y$2*O38*Q38 -> 0 | AY38: =AX38+AW38+AV38 -> 127.30667 | AZ38: =+AY38+AT38+AO38++AJ38+AE38+Z38 -> 636.53333 | BA38: =((AZ38-BB38-BC38-BD38-BE38-BF38)+BI38+BJ38+BK38+BL38+BM38+BN38+BO38) -> 1508.3333 | BG38: BONO | BI38: 300 | BL38: =271.8+300 -> 571.8 | BU38: 448
A39: 449 | B39: 28 | C39: =+C38+1 -> 9 | D39: Moran Hernandez Raul | E39: 1 | G39: 1 | I39: 1 | K39: 1 | M39: 1 | O39: 1 | Q39: =IF((E39+G39+I39+K39+M39+O39)=6,1,0) -> 1 | R39: =IF(Q39=1,3000,850) -> 3000 | S39: =+BH39 -> 0 | T39: =+BA39 -> 3000 | U39: =+BP39 -> 0 | V39: =+BG39 -> 0 | W39: =(R39-86.16)/6*E39 -> 485.64 | X39: =$Y$2*E39*Q39 -> 7.18 | Y39: =$Y$2*E39*Q39 -> 7.18 | Z39: =Y39+X39+W39 -> 500 | AB39: =(R39-86.16)/6*G39 -> 485.64 | AC39: =$Y$2*G39*Q39 -> 7.18 | AD39: =$Y$2*G39*Q39 -> 7.18 | AE39: =AD39+AC39+AB39 -> 500 | AG39: =(R39-86.16)/6*I39 -> 485.64 | AH39: =$Y$2*I39*Q39 -> 7.18 | AI39: =$Y$2*I39*Q39 -> 7.18 | AJ39: =AI39+AH39+AG39 -> 500 | AL39: =(R39-86.16)/6*K39 -> 485.64 | AM39: =$Y$2*K39*Q39 -> 7.18 | AN39: =$Y$2*K39*Q39 -> 7.18 | AO39: =AN39+AM39+AL39 -> 500 | AQ39: =(R39-86.16)/6*M39 -> 485.64 | AR39: =$Y$2*M39*Q39 -> 7.18 | AS39: =$Y$2*M39*Q39 -> 7.18 | AT39: =AS39+AR39+AQ39 -> 500 | AV39: =(R39-86.16)/6*O39 -> 485.64 | AW39: =$Y$2*O39*Q39 -> 7.18 | AX39: =$Y$2*O39*Q39 -> 7.18 | AY39: =AX39+AW39+AV39 -> 500 | AZ39: =+AY39+AT39+AO39++AJ39+AE39+Z39 -> 3000 | BA39: =((AZ39-BB39-BC39-BD39-BE39-BF39)+BI39+BJ39+BK39+BL39+BM39+BN39+BO39) -> 3000 | BU39: 449
A40: 448 | B40: 170 | C40: =+C39+1 -> 10 | D40: Ochoa Vital Edna Lizeth | E40: 1 | G40: 1 | I40: 1 | K40: 1 | M40: 1 | O40: 1 | Q40: =IF((E40+G40+I40+K40+M40+O40)=6,1,0) -> 1 | R40: =IF(Q40=1,1550,850) -> 1550 | S40: =+BH40 -> 0 | T40: =+BA40 -> 1950 | U40: =+BP40 -> 0 | V40: =+BG40 -> BONO+B ASIS | W40: =(R40-86.16)/6*E40 -> 243.97333 | X40: =$Y$2*E40*Q40 -> 7.18 | Y40: =$Y$2*E40*Q40 -> 7.18 | Z40: =Y40+X40+W40 -> 258.33333 | AB40: =(R40-86.16)/6*G40 -> 243.97333 | AC40: =$Y$2*G40*Q40 -> 7.18 | AD40: =$Y$2*G40*Q40 -> 7.18 | AE40: =AD40+AC40+AB40 -> 258.33333 | AG40: =(R40-86.16)/6*I40 -> 243.97333 | AH40: =$Y$2*I40*Q40 -> 7.18 | AI40: =$Y$2*I40*Q40 -> 7.18 | AJ40: =AI40+AH40+AG40 -> 258.33333 | AL40: =(R40-86.16)/6*K40 -> 243.97333 | AM40: =$Y$2*K40*Q40 -> 7.18 | AN40: =$Y$2*K40*Q40 -> 7.18 | AO40: =AN40+AM40+AL40 -> 258.33333 | AQ40: =(R40-86.16)/6*M40 -> 243.97333 | AR40: =$Y$2*M40*Q40 -> 7.18 | AS40: =$Y$2*M40*Q40 -> 7.18 | AT40: =AS40+AR40+AQ40 -> 258.33333 | AV40: =(R40-86.16)/6*O40 -> 243.97333 | AW40: =$Y$2*O40*Q40 -> 7.18 | AX40: =$Y$2*O40*Q40 -> 7.18 | AY40: =AX40+AW40+AV40 -> 258.33333 | AZ40: =+AY40+AT40+AO40++AJ40+AE40+Z40 -> 1550 | BA40: =((AZ40-BB40-BC40-BD40-BE40-BF40)+BI40+BJ40+BK40+BL40+BM40+BN40+BO40) -> 1950 | BG40: BONO+B ASIS | BI40: 250 | BJ40: 150 | BU40: 448
...

Sheet NOM
B1: SEMANA DEL 23 AL 29 DE JUNIO DEL 2025 | Y1: REBAJE X FALTAS
B2: TEJIDO
B3: TURNO1
B4: Responsable de llenado: | R4: Salario | S4: Bono productividad | T4: DIF NOM | U4: Bono extra | V4: Primas, finiquitos, etc | W4: otros | X4: Nominal
B5: # EMP | C5: NOMBRE | D5: PUESTO | E5: L | G5: M | I5: M | K5: J | M5: V | O5: S | Q5: D
A6: =A5+1 -> 1 | B6: 2 | C6: Antunez Requejo Gabriela | D6: Calidad | E6: 1 | F6: VAC | G6: 1 | H6: VAC | I6: 1 | J6: VAC | K6: 1 | L6: VAC | M6: 1 | N6: VAC | R6: 2300 | U6: 150 | X6: =+R6+S6+T6+U6+V6+W6 -> 2450
A7: =#REF!+1 -> #REF! | B7: 6 | C7: Balderas Balderas Myriam Ivet | D7: Lider | E7: 1 | F7: VAC | G7: 1 | H7: VAC | I7: 1 | J7: VAC | K7: 1 | L7: VAC | M7: 1 | N7: VAC | R7: 3000 | U7: 250 | X7: =+R7+S7+T7+U7+V7+W7 -> 3250
A8: =#REF!+1 -> #REF! | B8: 95 | C8: Carrillo Delgado Judith | D8: Operador | E8: 1 | G8: 1 | I8: 1 | K8: 1 | M8: 1 | R8: 1950 | S8: 250 | X8: =+R8+S8+T8+U8+V8+W8 -> 2200
B9: 222 | C9: Hernandez de la Rosa Maria Fernanda | D9: Operador | E9: 1 | F9: VAC | G9: 1 | I9: 1 | J9: VAC | K9: 1 | M9: 1 | O9: 1 | P9: VAC | R9: 1950 | S9: 200 | X9: =+R9+S9+T9+U9+V9+W9 -> 2150
B10: 260 | C10: Macias Mijares Jose De Jesus | D10: Creeler | E10: 1 | G10: 1 | I10: 1 | K10: 0 | L10: F | M10: 1 | R10: 1392.85 | X10: =+R10+S10+T10+U10+V10+W10 -> 1392.85 | Y10: -557.15
A11: =#REF!+1 -> #REF! | B11: 26 | C11: Medrano Suarez Jose Adolfo | D11: Mecanico | E11: 1 | F11: VAC | G11: 1 | H11: VAC | I11: 1 | J11: VAC | K11: 1 | L11: VAC | M11: 1 | N11: VAC | R11: 2500 | S11: 200 | U11: 200 | X11: =+R11+S11+T11+U11+V11+W11 -> 2900
A12: =#REF!+1 -> #REF! | B12: 28 | C12: Moran Hernandez Raul | D12: Mecanico | E12: 1 | G12: 1 | I12: 1 | K12: 1 | M12: 1 | R12: 5000 | X12: =+R12+S12+T12+U12+V12+W12 -> 5000
A13: =#REF!+1 -> #REF! | B13: 169 | C13: Ramirez Requejo Maria Guadalupe | D13: Operador | E13: 1 | G13: 1 | I13: 1 | K13: 1 | M13: 1 | R13: 1950 | S13: 200 | X13: =+R13+S13+T13+U13+V13+W13 -> 2150
A14: =#REF!+1 -> #REF! | B14: 146 | C14: Salazar Martinez Yohana Cecilia | D14: Operador | E14: 1 | G14: 1 | I14: 1 | J14: VAC | K14: 1 | M14: 1 | O14: 1 | P14: VAC | R14: 1950 | S14: 200 | X14: =+R14+S14+T14+U14+V14+W14 -> 2150
A15: =A13+1 -> #REF! | B15: 51 | C15: Valenzuela Rosales Jose Miguel | D15: Mecanico | E15: 1 | G15: 1 | I15: 1 | K15: 1 | M15: 1 | R15: 5000 | U15: 1000 | W15: 239.37 | X15: =+R15+S15+T15+U15+V15+W15 -> 6239.37
E16: =SUM(E6:E15) -> 10 | G16: =SUM(G6:G15) -> 10 | I16: =SUM(I6:I15) -> 10 | K16: =SUM(K6:K15) -> 9 | M16: =SUM(M6:M15) -> 10 | R16: =SUM(R6:R15) -> 26992.85 | S16: =SUM(S6:S15) -> 1050 | T16: =SUM(T6:T15) -> 0 | U16: =SUM(U6:U15) -> 1600 | V16: =SUM(V6:V15) -> 0 | W16: =SUM(W6:W15) -> 239.37 | X16: =SUM(X6:X15)-Y10-Y9 -> 30439.37
X17: =F29-X16 -> 0
D18: NOMINA | E18: EXTRA | F18: TOTAL | K18: L | M18: M | O18: M | Q18: J | S18: V | U18: S
B19: 1 | C19: LIDER | D19: =3000*B19 -> 3000 | E19: 0 | F19: =D19 -> 3000 | V19: PROM
B20: 1 | C20: CALIDAD | D20: =2300*B20 -> 2300 | E20: 0 | F20: =D20 -> 2300 | I20: LIDER | K20: 1 | M20: 1 | O20: 1 | Q20: 1 | S20: 1 | U20: 0 | V20: =AVERAGE(K20,M20,O20,Q20,S20) -> 1
B21: 3 | C21: MECANICO | D21: =2500+5000+5000 -> 12500 | E21: 0 | F21: =D21 -> 12500 | I21: CALIDAD | K21: 1 | M21: 1 | O21: 1 | Q21: 1 | S21: 1 | U21: 0 | V21: =AVERAGE(K21,M21,O21,Q21,S21) -> 1
B22: 5 | C22: MANUAL | D22: =1950*B22 -> 9750 | E22: 0 | F22: =D22 -> 9750 | I22: MECANICO | K22: 3 | M22: 3 | O22: 3 | Q22: 3 | S22: 3 | U22: 0 | V22: =AVERAGE(K22,M22,O22,Q22,S22) -> 3
I23: MANUAL | K23: 5 | M23: 5 | O23: 5 | Q23: 5 | S23: 5 | U23: 0 | V23: =AVERAGE(K23,M23,O23,Q23,S23) -> 5
B24: =SUM(B19:B23) -> 10 | F24: =SUM(F19:F23) -> 27550 | K24: =SUM(K20:K23) -> 10 | M24: =SUM(M20:M23) -> 10 | O24: =SUM(O20:O23) -> 10 | Q24: =SUM(Q20:Q23) -> 10 | S24: =SUM(S20:S23) -> 10 | U24: =SUM(U20:U23) -> 0 | V24: =AVERAGE(K24,M24,O24,Q24,S24) -> 10
E25: BONO | F25: =+S16 -> 1050
E26: BONOS EXTRA | F26: =+U16 -> 1600
E27: GRASEROS | F27: =W16 -> 239.37
F29: =SUM(F24:F28) -> 30439.37
B32: =+B1 -> SEMANA DEL 23 AL 29 DE JUNIO DEL 2025
B33: TURNO 2
B34: Responsable de llenado: | R34: Salario | S34: Bono productividas | T34: Bono de asitencia | U34: Bono extra | V34: Primas, finiquitos, etc | W34: otros | X34: Nominal
B35: # EMP | C35: NOMBRE | D35: PUESTO | E35: L | G35: M | I35: M | K35: J | M35: V | O35: S | Q35: D
B36: 59 | C36: Castro Viaña Mario Ivan | D36: Mecanico | E36: 1 | G36: 1 | I36: 1 | K36: 1 | M36: 1 | O36: 1 | R36: 2350 | S36: 200 | U36: 150 | X36: =+R36+S36+T36+U36+V36+W36 -> 2700
B37: 12 | C37: Diaz Martinez Angela Elizabeth | D37: Calidad | E37: 1 | G37: 1 | I37: 1 | K37: 1 | M37: 1 | O37: 1 | R37: 2300 | U37: 150 | X37: =+R37+S37+T37+U37+V37+W37 -> 2450
B38: 212 | C38: Hernandez Favela Margarita | D38: Operador | E38: 1 | G38: 1 | I38: 1 | K38: 1 | L38: VAC | M38: 1 | O38: 1 | R38: 1950 | S38: 200 | X38: =+R38+S38+T38+U38+V38+W38 -> 2150
E39: =SUM(E36:E38) -> 3 | G39: =SUM(G36:G38) -> 3 | I39: =SUM(I36:I38) -> 3 | K39: =SUM(K36:K38) -> 3 | M39: =SUM(M36:M38) -> 3 | O39: 3 | R39: =SUM(R36:R38) -> 6600 | S39: =SUM(S36:S38) -> 400 | T39: =SUM(T36:T38) -> 0 | U39: =SUM(U36:U38) -> 300 | V39: =SUM(V36:V38) -> 0 | W39: =SUM(W36:W38) -> 0 | X39: =SUM(X36:X38)-Y36 -> 7300
X40: =F51-X39 -> 0
D41: NOMINA | E41: EXTRA | F41: TOTAL
B42: 0 | C42: SUPERVISORA | D42: 0 | E42: 0 | F42: =D42 -> 0 | K42: L | M42: M | O42: M | Q42: J | S42: V | U42: S
B43: 1 | C43: CALIDAD | D43: =2300*B43 -> 2300 | E43: 0 | F43: =D43 -> 2300 | V43: PROM
...

Sheet LISTAS
B2: SEMANA DEL 16 AL 22 JUNIO DEL 2025 | L2: PARAMETROS A EVALUAR PARA BONO
L3: Deteccion de defectos | M3: limpieza de area | N3: Llenado de formatos | O3: Permisos | P3: Retardos | Q3: BONO
C4: TEJIDO
B5: TURNO1
B6: Responsable de llenado: Myriam Iveth Balderas Balderas
B7: # EMP | C7: NOMBRE | D7: PUESTO | E7: L | F7: M | G7: M | H7: J | I7: V | J7: S | K7: D
A8: 1 | B8: 2 | C8: Antunez Requejo Gabriela | D8: Calidad | E8: VAC | F8: VAC | G8: VAC | H8: VAC | I8: VAC
A9: 2 | B9: 6 | C9: Balderas Balderas Myriam Ivet | D9: Lider | E9: VAC | F9: VAC | G9: VAC | H9: VAC | I9: VAC
A10: 3 | B10: 95 | C10: Carrillo Delgado Judith | D10: Operador | E10: 1 | F10: 1 | G10: 1 | H10: 1 | I10: 1
A11: 4 | B11: 222 | C11: Hernandez de la Rosa Maria Fernanda | D11: Operador | E11: VAC | F11: 1 | G11: VAC | H11: 1 | I11: 1 | J11: VAC
A12: 5 | B12: 260 | C12: Macias Mijares Jose De Jesus | D12: Creeler | E12: 1 | F12: 1 | G12: 1 | H12: F | I12: 1
A13: 6 | B13: 26 | C13: Medrano Suarez Jose Adolfo | D13: Mecanico | E13: VAC | F13: VAC | G13: VAC | H13: VAC | I13: VAC
A14: 7 | B14: 28 | C14: Moran Hernandez Raul | D14: Mecanico | E14: 1 | F14: 1 | G14: 1 | H14: 1 | I14: 1
A15: 8 | B15: 169 | C15: Ramirez Requejo Maria Guadalupe | D15: Operador | E15: 1 | F15: 1 | G15: 1 | H15: 1 | I15: 1 | J15: 1
A16: 9 | B16: 146 | C16: Salazar Martinez Yohana Cecilia | D16: Operador | E16: 1 | F16: 1 | G16: 1 | H16: 1 | I16: 1
A17: 10 | B17: 261 | C17: Valenzuela Gonzalez Cristian Omar | D17: Creeler | E17: D | F17: D | G17: D | H17: D | I17: D
A18: 11 | B18: 51 | C18: Valenzuela Rosales Jose Miguel | D18: Mecanico | E18: 1 | F18: 1 | G18: 1 | H18: 1 | I18: 1
A19: 12 | B19: 265 | C19: Valenzuela Ruiz Brisa Iris | D19: Operador | E19: D | F19: D | G19: D | H19: D | I19: D
B21: =+B2 -> SEMANA DEL 16 AL 22 JUNIO DEL 2025 | L21: PARAMETROS A EVALUAR PARA BONO
L22: Deteccion de defectos | M22: limpieza de area | N22: Llenado de formatos | O22: Permisos | P22: Retardos | Q22: BONO
C23: TEJIDO
B24: TURNO1
B25: Responsable de llenado: Myriam Iveth Balderas Balderas
B26: # EMP | C26: NOMBRE | D26: PUESTO | E26: L | F26: M | G26: M | H26: J | I26: V | J26: S | K26: D
A27: 1 | B27: 59 | C27: Castro Viaña Mario Ivan | D27: Mecanico | E27: A | F27: A | G27: A | H27: A | I27: A | J27: A
A28: 2 | B28: 12 | C28: Diaz Martinez Angela Elizabeth | D28: calidad | E28: A | F28: A | G28: A | H28: A | I28: A | J28: A
A29: 3 | B29: 212 | C29: Hernandez Favela Margarita | D29: operador | E29: A | F29: A | G29: A | H29: VAC | I29: A | J29: A
B31: =+B2 -> SEMANA DEL 16 AL 22 JUNIO DEL 2025 | L31: PARAMETROS A EVALUAR PARA BONO
B32: TEJIDO | L32: Deteccion de defectos | M32: limpieza de area | N32: Llenado de formatos | O32: Permisos | P32: Retardos | Q32: BONO
B33: TURNO 3
B34: Responsable de llenado:Perez Suarez Herber Antony
B35: # EMP | C35: NOMBRE | D35: PUESTO | E35: L | F35: M | G35: M | H35: J | I35: V | J35: S | K35: D
A36: 1 | B36: 251 | C36: Balderas Aguilar Yhair Otoniel | D36: Operador | E36: VAC | F36: VAC | G36: VAC | H36: VAC | I36: 1
A37: 2 | B37: 250 | C37: Botello Amaya Brenda Cecilia | D37: Calidad | E37: 1 | F37: 1 | G37: 1 | H37: 1 | I37: 1
A38: 4 | B38: 214 | C38: Gress Padilla Leidy Daniela | D38: Operador | E38: 1 | F38: VAC | G38: 1 | H38: 1 | I38: 1
A39: 6 | B39: 215 | C39: Holguin Salas Hilda Yudit | D39: Operador | E39: VAC | F39: VAC | G39: 1 | H39: 1 | I39: 1
A40: 7 | B40: 27 | C40: Minor Flores Adilene | D40: Calidad | E40: VAC | F40: VAC | G40: VAC | H40: VAC | I40: VAC
A41: 8 | B41: 159 | C41: Perez Suarez Herber Antony | D41: Mecanico | E41: 1 | F41: 1 | G41: 1 | H41: 1 | I41: 1
A42: 9 | B42: 33 | C42: Ramirez Vital Jose Armando | D42: Operador | E42: 1 | F42: 1 | G42: VAC | H42: VAC | I42: VAC
B43: 266 | C43: Rubio Resendiz Emilio | D43: Creeler | E43: 1 | F43: 1 | G43: 1 | H43: 1 | I43: 1
...

Sheet resumen rh
A6: NOM 28 AL 04 DE MAYO 2025
A7: =+AVERAGE(C7,E7,G7,I7,K7) -> 10 | C7: =NOM!K24 -> 10 | E7: =NOM!M24 -> 10 | G7: =NOM!O24 -> 10 | I7: =NOM!Q24 -> 10 | K7: =NOM!S24 -> 10 | M7: =NOM!U24 -> 0 | N7: TEJIDO
A8: =+AVERAGE(C8,E8,G8,I8,K8,M8) -> 3 | C8: =NOM!E39 -> 3 | E8: =NOM!G39 -> 3 | G8: =NOM!I39 -> 3 | I8: =NOM!K39 -> 3 | K8: =NOM!M39 -> 3 | M8: =NOM!O39 -> 3 | N8: TEJIDO 2
A9: =+AVERAGE(C9,E9,G9,I9,K9) -> 10 | C9: =NOM!K77 -> 10 | E9: =NOM!M77 -> 10 | G9: =NOM!O77 -> 10 | I9: =NOM!Q77 -> 10 | K9: =NOM!S77 -> 10 | M9: =NOM!U77 -> 0 | N9: TEJIDO 3
A10: =+AVERAGE(C10,E10,G10,I10,K10,M10) -> 7 | C10: =NOM!K179 -> 7 | E10: =NOM!M179 -> 7 | G10: =NOM!O179 -> 7 | I10: =NOM!Q179 -> 7 | K10: =NOM!S179 -> 7 | M10: =NOM!U179 -> 7 | N10: PUÑO
A11: =+AVERAGE(C11,E11,G11,I11,K11,M11) -> 5 | C11: =NOM!K207 -> 5 | E11: =NOM!M207 -> 5 | G11: =NOM!O207 -> 5 | I11: =NOM!Q207 -> 5 | K11: =NOM!S207 -> 5 | M11: =NOM!U207 -> 5 | N11: PUÑO2
A12: =+AVERAGE(C12,E12,G12,I12,K12) -> 5 | C12: =NOM!K232 -> 5 | E12: =NOM!M232 -> 5 | G12: =NOM!O232 -> 5 | I12: =NOM!Q232 -> 5 | K12: =NOM!S232 -> 5 | M12: =NOM!U232 -> 0 | N12: PUÑO3
A13: =+AVERAGE(C13,E13,G13,I13,K13,M13) -> 7.3333333 | C13: =NOM!K106 -> 8 | E13: =NOM!M106 -> 9 | G13: =NOM!O106 -> 9 | I13: =NOM!Q106 -> 9 | K13: =NOM!S106 -> 9 | M13: =NOM!U106 -> 0 | N13: AE
A14: =+AVERAGE(C14,E14,G14,I14,K14) -> 0 | C14: 0 | E14: 0 | G14: 0 | I14: 0 | K14: 0 | M14: 0 | N14: AE 2
A15: =+AVERAGE(C15,E15,G15,I15,K15) -> 8 | C15: =NOM!K154 -> 8 | E15: =NOM!M154 -> 8 | G15: =NOM!O154 -> 8 | I15: =NOM!Q154 -> 8 | K15: =NOM!S154 -> 8 | M15: =NOM!U154 -> 0 | N15: AE 3
A16: =+AVERAGE(C16,E16,G16,I16,K16) -> 10 | C16: =NOM!L270 -> 9 | E16: =NOM!N270 -> 11 | G16: =NOM!P270 -> 10 | I16: =NOM!R270 -> 10 | K16: =NOM!T270 -> 10 | M16: =NOM!V270 -> 0 | N16: TEJIDO LEON
A17: =+AVERAGE(C17,E17,G17,I17,K17) -> 1 | C17: =NOM!E280 -> 1 | E17: =NOM!G280 -> 1 | G17: =NOM!I280 -> 1 | I17: =NOM!K280 -> 1 | K17: =NOM!M280 -> 1 | M17: =NOM!O280 -> 1 | N17: APOYO LG
A19: =+AVERAGE(C19,E19,G19,I19,K19) -> 67.8 | C19: =SUM(C7:C18) -> 66 | E19: =SUM(E7:E18) -> 69 | G19: =SUM(G7:G18) -> 68 | I19: =SUM(I7:I18) -> 68 | K19: =SUM(K7:K18) -> 68 | M19: =SUM(M7:M18) -> 16 | N19: TOT

Sheet CHECADAS
A1: Nominas
A2: Numero | B2: NombreCompleto | C2: FechaInicio | D2: FechaFin | E2: L.Entrada | F2: L.Salida | G2: MA.Entrada | H2: MA.Salida | I2: MI.Entrada | J2: MI.Salida | K2: J.Entrada | L2: J.Salida | M2: V.Entrada | N2: V.Salida | O2: S.Entrada | P2: S.Salida | Q2: D.Entrada | R2: D.Salida
A3: 107 | B3: SAMUEL CHAVARRIA MACHADO | C3: 2025-06-23 | D3: 2025-06-29 | E3: 15:40:00 | F3: 0.9849537 | I3: 03:26:56 p. m. | J3: 0.98461806 | K3: 15:26:00 | L3: 0.98501157 | M3: 03:39:04 p. m. | N3: 0.98204861 | O3: 0.64471065 | P3: 0.77542824
A4: 118 | B4: MARIA FERNANDA ROSALES GONZALEZ | C4: 2025-06-23 | D4: 2025-06-29 | E4: 0.98761574 | F4: 0.31275463 | G4: 0.9809375 | H4: 0.31299769 | I4: 0.98175926 | J4: 0.31333333 | K4: 0.98085648 | L4: 0.31296296 | M4: 0.97664352 | N4: 07:30:38 a. m.
A5: 12 | B5: ANGELA ELIZABETH DIAZ MARTINEZ | C5: 2025-06-23 | D5: 2025-06-29 | E5: 15:27:00 | F5: 23:32:00 | G5: 15:27:00 | H5: 0.9799537 | I5: 15:24:00 | J5: 23:36:00 | K5: 15:30:00 | L5: 23:33:00 | M5: 0.65690972 | N5: 0.85211806
A6: 135 | B6: SUGEY MARISOL MARTINEZ ROSALES | C6: 2025-06-23 | D6: 2025-06-29 | F6: 0.31328704 | G6: 0.98099537 | H6: 0.31305556 | I6: 0.98181713 | J6: 0.31715278 | K6: 0.9809375 | L6: 07:30:50 a. m. | M6: |
A7: 141 | B7: MA. ISABEL VARGAS MENDEZ | C7: 2025-06-23 | D7: 2025-06-29 | E7: 07:26:00 | F7: 15:31:00 | G7: 07:25:00 | H7: 15:31:00 | I7: 07:24:00 | J7: 15:31:00 | K7: 07:25:00 | L7: 15:35:00 | M7: 07:25:00 | N7: 03:33:53 p. m. | O7: 0.30895833 | P7: 0.6475463
A8: 1446 | B8: SAUL BAUTISTA REVUELTAS | C8: 2025-06-23 | D8: 2025-06-29
A9: 146 | B9: YOHANA CECILIA SALAZAR MARTINEZ | C9: 2025-06-23 | D9: 2025-06-29 | E9: 07:16:00 | F9: 0.64829861 | G9: 07:22:00 | H9: 03:31:44 p. m. | I9: VAC | K9: 07:20:00 | L9: 03:31:18 p. m. | M9: 07:20:50 a. m. | N9: 0.64673611 | O9: VAC
A10: 158 | B10: JOSE ALBERTO CABALLERO COYOC | C10: 2025-06-23 | D10: 2025-06-29 | E10: 0.64917824 | F10: 0.98047454 | G10: 0.6421412 | H10: 0.98077546 | I10: 0.65003472 | J10: 11:37:39 p. m. | K10: 0.64821759 | L10: 0.98600694 | M10: 03:33:02 p. m. | N10: 11:50:48 p. m. | O10: 0.6515625 | P10: 0.85554398
A11: 159 | B11: HERBER ANTONY PEREZ SUAREZ | C11: 2025-06-23 | D11: 2025-06-29 | E11: 0.97439815 | F11: 07:32:00 | G11: 11:26:08 p. m. | H11: 07:38:00 | I11: 0.98068287 | J11: 07:35:00 | K11: 0.97409722 | L11: 07:32:00 | M11: 11:30:10 p. m. | N11: 0.31988426
A12: 165 | B12: DIEGO FRANCO ALATORRE | C12: 2025-06-23 | D12: 2025-06-29
A13: 166 | B13: ACACIA ENRIQUEZ GUTIERREZ | C13: 2025-06-23 | D13: 2025-06-29 | E13: 07:26:00 | F13: 15:31:00 | G13: 07:25:00 | H13: 15:31:00 | I13: 07:24:00 | J13: 15:31:00 | K13: 07:24:00 | L13: 15:35:00 | M13: 07:25:00 | N13: 0.64849537 | O13: VAC
A14: 169 | B14: MARIA GUADALUPE RAMIREZ REQUEJO | C14: 2025-06-23 | D14: 2025-06-29 | E14: 0.64372685 | F14: 0.98096065 | G14: 03:28:43 p. m. | H14: 0.97938657 | I14: 0.6468287 | J14: 0.97927083 | K14: 0.64704861 | L14: 11:31:00 p. m. | M14: 0.64355324 | N14: 0.98238426 | O14: 0.6437037 | P14: 0.85217593
A15: 172 | B15: MARIA ELENA HERNANDEZ CAMPISTA | C15: 2025-06-23 | D15: 2025-06-29 | E15: 0.28488426 | F15: 0.68074074 | G15: 0.28447917 | H15: 0.68084491 | I15: 0.28356481 | J15: 0.68059028 | K15: 0.28458333 | L15: 0.680625 | M15: 0.28325231 | N15: 0.68131944
A16: 19 | B16: ELIZABETH GARCIA NUÑEZ | C16: 2025-06-23 | D16: 2025-06-29 | E16: 07:40:00 | F16: 15:42:00 | G16: 07:31:00 | H16: 15:33:00 | I16: 07:31:00 | J16: 15:37:00 | K16: 07:34:00 | L16: 15:40:00 | M16: 07:34:00 | N16: 0.65541667 | O16: 0.32449074 | P16: 03:45:47 p. m.
A17: 2 | B17: GABRIELA ANTUNEZ REQUEJO | C17: 2025-06-23 | D17: 2025-06-29 | E17: VAC | G17: VAC | I17: VAC | K17: VAC | M17: VAC
A18: 210 | B18: NANCY LORENA PADILLA ARMIJO | C18: 2025-06-23 | D18: 2025-06-29 | E18: 0.98518519 | F18: 0.31322917 | G18: 0.98642361 | H18: 0.31356481 | I18: 0.98189815 | J18: 0.31388889 | K18: 0.98459491 | L18: 0.31425926 | M18: 11:36:59 p. m. | N18: 07:31:44 a. m.
A19: 212 | B19: MARGARITA HERNANDEZ FAVELA | C19: 2025-06-23 | D19: 2025-06-29 | E19: 15:27:00 | F19: 0.98119213 | G19: 15:26:00 | H19: 0.9799537 | I19: 15:24:00 | J19: 0.97994213 | K19: VAC | M19: 03:30:58 p. m. | N19: 0.97939815 | O19: 03:27:37 p. m. | P19: 08:29:54 p. m.
A20: 214 | B20: LEIDY DANIELA GRESS PADILLA | C20: 2025-06-23 | D20: 2025-06-29 | E20: 11:21:35 p. m. | F20: 07:30:00 | I20: 11:12:17 p. m. | J20: 0.31288194 | K20: 0.97017361 | L20: 07:30:00 | M20: 0.96686343 | N20: 0.31263889
A21: 215 | B21: HILDA YUDITH HOLGUIN SALAS | C21: 2025-06-23 | D21: 2025-06-29 | E21: VAC | G21: VAC | I21: 0.96733796 | J21: 07:30:00 | K21: 10:47:12 p. m. | L21: 07:30:00 | M21: 0.94515046 | N21: 07:30:07 a. m.
A22: 220 | B22: PEDRO VARGAS TORRES | C22: 2025-06-23 | D22: 2025-06-29 | E22: 07:28:00 | F22: 0.64707176 | G22: 07:30:00 | H22: 0.64732639 | I22: 07:29:00 | J22: 03:31:42 p. m. | K22: 07:30:00 | M22: 07:29:00 | N22: 0.64865741 | O22: 07:35:54 a. m. | P22: 03:32:51 p. m.
A23: 222 | B23: MARIA FERNANDA HERNANDEZ DE LA ROSA | C23: 2025-06-23 | D23: 2025-06-29 | E23: VAC | G23: 07:30:00 | H23: 0.64663194 | I23: 0.30542824 | J23: 0.64642361 | K23: VAC | M23: 07:32:00 | O23: VAC
A24: 226 | B24: JOSE URIEL MORENO MARTINEZ | C24: 2025-06-23 | D24: 2025-06-29 | E24: 07:09:13 a. m. | F24: 0.64662037 | G24: 07:06:44 a. m. | H24: 0.64869213 | I24: 0.31890046 | J24: 0.64717593 | K24: 07:32:13 a. m. | L24: 0.64601852 | M24: 0.31357639 | N24: 0.64641204 | O24: 0.31680556
A25: 227 | B25: JOSE LUIS MARTINEZ ROSALES | C25: 2025-06-23 | D25: 2025-06-29 | E25: 0.95601852 | F25: 07:30:00 | G25: 0.9519213 | H25: 07:30:00 | I25: 10:52:51 p. m. | J25: 07:30:00 | K25: 10:48:05 p. m. | L25: 07:31:00 | M25: 0.98649306 | N25: 0.31375
A26: 228 | B26: HAXEL RODRIGO TOSTADO SIFUENTES | C26: 2025-06-23 | D26: 2025-06-29 | E26: 0.98127315 | F26: 0.31263889 | G26: 0.98263889 | H26: 0.31280093 | I26: 0.98269676 | J26: 0.31311343 | K26: 0.98208333 | L26: 0.3127662 | M26: 11:37:02 p. m. | N26: 07:30:15 a. m.
A27: 230 | B27: PRINCE ANAIS LLAMAS PEREZ | C27: 2025-06-23 | D27: 2025-06-29 | E27: 07:16:00 | F27: 0.79332176 | G27: 07:12:46 a. m. | H27: 0.64652778 | I27: 07:15:00 | J27: 0.64605324 | K27: 0.30059028 | L27: 0.64615741 | M27: 07:16:00 | N27: 0.64628472 | O27: 0.31861111 | P27: 0.64677083 | Q27: 0.35207176 | R27: 0.64725694
A28: 235 | B28: ANGEL DE JESUS MORENO MARTINEZ | C28: 2025-06-23 | D28: 2025-06-29 | E28: T*T | F28: T*T | G28: T*T | H28: T*T | I28: T*T | J28: T*T | K28: T*T | L28: T*T | M28: T*T | N28: T*T | O28: T*T | P28: T*T | Q28: T*T
A29: 239 | B29: ROSA VELIA CORDONA PEREZ | C29: 2025-06-23 | D29: 2025-06-29 | E29: 0.30309028 | F29: 0.79320602 | G29: 07:12:37 a. m. | H29: 0.79491898 | I29: 07:15:17 a. m. | J29: 0.70850694 | K29: 0.3006713 | L29: 0.793125 | M29: 07:16:09 a. m. | N29: 0.64618056 | O29: 0.64672454 | P29: 0.35211806 | Q29: 03:32:13 p. m.
A30: 241 | B30: MONSERRAT GUADALUPE MOLINA SIFUENTES | C30: 2025-06-23 | D30: 2025-06-29 | E30: 0.29384259 | F30: 0.6462963 | G30: 0.29850694 | H30: 0.64659722 | I30: 0.29415509 | J30: 03:30:22 p. m. | K30: 0.29313657 | L30: 0.64623843 | M30: 0.29640046 | N30: 0.64622685 | O30: 0.29138889 | P30: 0.64666667
A31: 242 | B31: JESUS MARIA VILLEGAS REYES | C31: 2025-06-23 | D31: 2025-06-29 | E31: VAC | G31: VAC | I31: VAC | K31: VAC | M31: VAC
A32: 245 | B32: PEDRO FRANCISCO VARGAS CASTAÑEDA | C32: 2025-06-23 | D32: 2025-06-29 | E32: FALTA | G32: 07:19:00 | H32: 0.7080787 | I32: 0.30152778 | J32: 0.70599537 | K32: 07:20:00 | L32: 0.70553241 | M32: 07:16:00 | N32: 0.70625
A33: 251 | B33: YHAIR OTONIEL BALDERAS AGUILAR | C33: 2025-06-23 | D33: 2025-06-29 | E33: VAC | G33: VAC | I33: VAC | K33: VAC | M33: 0.94510417 | N33: 0.3125463
A34: 254 | B34: ANGELICA NUÑEZ VIAÑA | C34: 2025-06-23 | D34: 2025-06-29 | E34: 23:11:00 | F34: 07:30:00 | G34: 23:19:00 | H34: 07:30:00 | I34: 23:20:00 | J34: 07:31:00 | K34: 23:21:00 | L34: 07:30:00 | M34: 0.9694213 | N34: 0.31355324
A35: 256 | B35: JORDAN MISSAEL GONZALEZ REYES | C35: 2025-06-23 | D35: 2025-06-29 | E35: 07:47:00 | F35: 17:01:00 | G35: 07:41:00 | H35: 17:00:00 | I35: 07:41:00 | J35: 04:57:37 p. m. | K35: 07:41:00 | L35: 0.705625 | M35: 07:37:00 | N35: 0.70628472 | O35: 0.32936343 | P35: 0.5296875
A36: 26 | B36: JOSE ADOLFO MEDRANO SUAREZ | C36: 2025-06-23 | D36: 2025-06-29 | E36: VAC | G36: VAC | I36: VAC | K36: VAC | M36: VAC
A37: 260 | B37: JOSE DE JESUS MACIAS MIJARES | C37: 2025-06-23 | D37: 2025-06-29 | E37: 07:47:00 | F37: 17:01:00 | G37: 07:45:00 | I37: 07:43:00 | J37: 04:57:48 p. m. | K37: FALTA | M37: 07:35:00 | N37: 0.70631944
A38: 261 | B38: CRISTIAN OMAR VALENZUELA ROSALES | C38: 2025-06-23 | D38: 2025-06-29 | E38: B | G38: B | I38: B | K38: B | M38: B
A39: 262 | B39: ZEIDA MARLEN MORENO MARTINEZ | C39: 2025-06-23 | D39: 2025-06-29 | E39: 07:16:00 | F39: 15:30:00 | G39: 07:12:00 | H39: 15:31:00 | I39: 07:21:00 | J39: 15:30:00 | K39: 07:32:00 | L39: 15:30:00 | M39: 07:16:00 | N39: 03:30:48 p. m. | O39: 0.3075 | P39: 0.64680556
A40: 264 | B40: JOSE ALFREDO CASTAÑEDA FLORES | C40: 2025-06-23 | D40: 2025-06-29 | E40: 0.63988426 | F40: 11:30:25 p. m. | G40: 0.63400463 | H40: 0.97961806 | I40: 0.63506944 | J40: 0.9793287 | K40: 0.63511574 | L40: 0.80033565 | N40: 0.97986111 | O40: 0.63528935 | P40: 0.85420139
...

Sheet REPORTE
A1: Date | B1: Device ID | C1: Device | D1: User Group | E1: User | F1: Event
A2: 45837.972 | B2: 542361075 | C2: FaceStation 2 542361075 (192.168.50.205) | D2: All Users | E2: 94 | F2: 1:N authentication succeeded (Face)
A3: 45837.647 | B3: 542361075 | C3: FaceStation 2 542361075 (192.168.50.205) | D3: All Users | E3: 239 | F3: 1:N authentication succeeded (Face)
A4: 45837.647 | B4: 542361075 | C4: FaceStation 2 542361075 (192.168.50.205) | D4: All Users | E4: 73 | F4: 1:N authentication succeeded (Face)
A5: 45837.647 | B5: 542361075 | C5: FaceStation 2 542361075 (192.168.50.205) | D5: All Users | E5: 230 | F5: 1:N authentication succeeded (Face)
A6: 45837.352 | B6: 542361075 | C6: FaceStation 2 542361075 (192.168.50.205) | D6: All Users | E6: 239 | F6: 1:N authentication succeeded (Face)
A7: 45837.352 | B7: 542361075 | C7: FaceStation 2 542361075 (192.168.50.205) | D7: All Users | E7: 230 | F7: 1:N authentication succeeded (Face)
A8: 45837.34 | B8: 542361075 | C8: FaceStation 2 542361075 (192.168.50.205) | D8: All Users | E8: 73 | F8: 1:N authentication succeeded (Face)
A9: 45837.323 | B9: 542361075 | C9: FaceStation 2 542361075 (192.168.50.205) | D9: All Users | E9: 35 | F9: 1:N authentication succeeded (Face)
A10: 45837.315 | B10: 542361075 | C10: FaceStation 2 542361075 (192.168.50.205) | D10: All Users | E10: 63 | F10: 1:N authentication succeeded (Face)
A11: 45837.315 | B11: 542361075 | C11: FaceStation 2 542361075 (192.168.50.205) | D11: All Users | E11: 94 | F11: 1:N authentication succeeded (Face)
A12: 45837.284 | B12: 542361075 | C12: FaceStation 2 542361075 (192.168.50.205) | F12: Tamper off
A13: 45837.284 | B13: 542361075 | C13: FaceStation 2 542361075 (192.168.50.205) | F13: Device started
A14: 45837.284 | B14: 542361075 | C14: FaceStation 2 542361075 (192.168.50.205) | F14: Network connected
A15: 45836.973 | B15: 542361075 | C15: FaceStation 2 542361075 (192.168.50.205) | D15: All Users | E15: 94 | F15: 1:N authentication succeeded (Face)
A16: 45836.856 | B16: 542361075 | C16: FaceStation 2 542361075 (192.168.50.205) | D16: All Users | E16: 70 | F16: 1:N authentication succeeded (Face)
A17: 45836.856 | B17: 542361075 | C17: FaceStation 2 542361075 (192.168.50.205) | D17: All Users | E17: 30 | F17: 1:N authentication succeeded (Face)
A18: 45836.856 | B18: 542361075 | C18: FaceStation 2 542361075 (192.168.50.205) | D18: All Users | E18: 158 | F18: 1:N authentication succeeded (Face)
A19: 45836.855 | B19: 542361075 | C19: FaceStation 2 542361075 (192.168.50.205) | D19: All Users | E19: 235 | F19: 1:N authentication succeeded (Face)
A20: 45836.854 | B20: 542361075 | C20: FaceStation 2 542361075 (192.168.50.205) | D20: All Users | E20: 271 | F20: 1:N authentication succeeded (Face)
A21: 45836.854 | B21: 542361075 | C21: FaceStation 2 542361075 (192.168.50.205) | D21: All Users | E21: 264 | F21: 1:N authentication succeeded (Face)
A22: 45836.854 | B22: 542361075 | C22: FaceStation 2 542361075 (192.168.50.205) | D22: All Users | E22: 81 | F22: 1:N authentication succeeded (Face)
A23: 45836.854 | B23: 542361075 | C23: FaceStation 2 542361075 (192.168.50.205) | D23: All Users | E23: 212 | F23: 1:N authentication succeeded (Face)
A24: 45836.852 | B24: 542361075 | C24: FaceStation 2 542361075 (192.168.50.205) | D24: All Users | E24: 169 | F24: 1:N authentication succeeded (Face)
A25: 45836.852 | B25: 542361075 | C25: FaceStation 2 542361075 (192.168.50.205) | D25: All Users | E25: 12 | F25: 1:N authentication succeeded (Face)
A26: 45836.813 | B26: 542361075 | C26: FaceStation 2 542361075 (192.168.50.205) | D26: All Users | E26: 264 | F26: 1:N authentication succeeded (Face)
... A32: 45836.657 | B32: 542361075 | C32: FaceStation 2 542361075 (192.168.50.205) | D32: All Users | E32: 19 | F32: 1:N authentication succeeded (Face)
A33: 45836.657 | B33: 542361075 | C33: FaceStation 2 542361075 (192.168.50.205) | F33: Authentication failed (Timeout)
A34: 45836.657 | B34: 542361075 | C34: FaceStation 2 542361075 (192.168.50.205) | D34: All Users | E34: 247 | F34: 1:N authentication succeeded (Face)
A35: 45836.657 | B35: 542361075 | C35: FaceStation 2 542361075 (192.168.50.205) | F35: Authentication failed (Timeout)
A36: 45836.652 | B36: 542361075 | C36: FaceStation 2 542361075 (192.168.50.205) | D36: All Users | E36: 158 | F36: 1:N authentication succeeded (Face)
A37: 45836.65 | B37: 542361075 | C37: FaceStation 2 542361075 (192.168.50.205) | D37: All Users | E37: 271 | F37: 1:N authentication succeeded (Face)
A38: 45836.648 | B38: 542361075 | C38: FaceStation 2 542361075 (192.168.50.205) | D38: All Users | E38: 51 | F38: 1:N authentication succeeded (Face)
A39: 45836.648 | B39: 542361075 | C39: FaceStation 2 542361075 (192.168.50.205) | D39: All Users | E39: 220 | F39: 1:N authentication succeeded (Face)
A40: 45836.648 | B40: 542361075 | C40: FaceStation 2 542361075 (192.168.50.205) | D40: All Users | E40: 141 | F40: 1:N authentication succeeded (Face)
A41: 45836.648 | B41: 542361075 | C41: FaceStation 2 542361075 (192.168.50.205) | D41: All Users | E41: 145 | F41: 1:N authentication succeeded (Face)
A42: 45836.647 | B42: 542361075 | C42: FaceStation 2 542361075 (192.168.50.205) | D42: All Users | E42: 30 | F42: 1:N authentication succeeded (Face)
A43: 45836.647 | B43: 542361075 | C43: FaceStation 2 542361075 (192.168.50.205) | D43: All Users | E43: 262 | F43: 1:N authentication succeeded (Face)
A44: 45836.647 | B44: 542361075 | C44: FaceStation 2 542361075 (192.168.50.205) | D44: All Users | E44: 230 | F44: 1:N authentication succeeded (Face)
A45: 45836.647 | B45: 542361075 | C45: FaceStation 2 542361075 (192.168.50.205) | D45: All Users | E45: 239 | F45: 1:N authentication succeeded (Face)
...
